Workbook
Name v: 'Ряд'!$H$5:$H$40
Name d: 'Ряд'!$J$6:$J$40
Name cor_kb: 'Ряд'!$O$5:$O$40
Name d_cor_kb: 'Ряд'!$P$6:$P$40
Name cor_ms: 'Ряд'!$R$5:$R$40
Name d_cor_ms: 'Ряд'!$S$6:$S$40
Name p_conf: 'Параметры'!$C$5
Name z_p: 'Параметры'!$C$6
Name k_G26: 'Параметры'!$C$7
Name L_reg: 'Параметры'!$C$8
Name T_cikl: 'Параметры'!$C$9
Name por_sk: 'Параметры'!$C$10
Name por_zaim: 'Параметры'!$C$11

Sheet Как защищать
A1: Расчётный лист по топ-20: как им пользоваться на комитете
A2: Редакция 14.09.2026. Собрано из data/top20_monthly_2023_08_2026_07.csv сборщиком build/raschet_list.py — правки вносятся в скрипт, а не в готовый файл. Сверка: python3 raschet_list.py --verify.
A4: Что в книге | B4: «Ряд» — 36 точек и всё, что считается построчно, обе базы капитала рядом. «Параметры» — семь входов, из них вычисляются два. «Расчёт» — каждое опубликованное число живой формулой против напечатанного. «Обоснование M(T)» — четыре проверки допущений формулы буфера. «Зоны» — разметка и где мы сейчас. «Две сигмы» — остаток Р-Д1. «Триггеры» — все 35 приростов.
A5: Главное свойство | B5: В книге нет ни одного вбитого руками результата, кроме одного помеченного (бутстрап). Любое число со слайда выделяется в колонке «Значение», и в строке формул видно, из чего оно получено. Несогласный с параметром меняет его на листе «Параметры», и вся книга пересчитывается при нём.
A6: «Откуда 108,63» | B6: Уровень 95 % задан в регуляторной базе капитала. С 01.01.2026 знаменатель метрики — балансовый капитал (Г26), k = 0,8745 есть отношение баз. 108,63 — тот же уровень в новой базе. Второй, независимый путь: квантиль 90 % ряда плюс запас на три месяца даёт 108,58. Сходимость двух путей на 0,05 пп и есть довод, что уровень не подогнан.
A7: «Почему корень из T» | B7: Складываются дисперсии, а не с.к.о.: сумма T независимых приростов имеет дисперсию T·σ², то есть разброс σ·√T. Держится это ровно на независимости. Лист «Обоснование M(T)», блок 1: автокорреляция −0,08 при пороге 0,34; фактический разброс трёхмесячных изменений 6,40 против модельных 7,04 — модель ЗАВЫШАЕТ, то есть ошибается в безопасную сторону.
A8: «Почему нормальное распределение» | B8: Нужна нормальность не приростов, а их трёхмесячной СУММЫ, к которой буфер и применяется. У приростов асимметрия 0,67, у суммы — 0,04. Жарк–Бера на приростах 2,70 при критических 5,99. И z(0,90) = 1,28 лежит в теле распределения, а не в хвосте: ошибки нормальности бьют на 99 %, не на 90 %. Лист «Обоснование M(T)», блок 2.
A9: «А буфер не выдуман» | B9: Три непараметрических способа дают 9,29, 9,35 и 9,37 против модельных 9,03 — разброс 3,6 % при собственной погрешности σ в ±1,09. И проверка на факте: движение апрель→июль 2026 составило +8,24 пп, то есть 91 % буфера. Буфер не подушка на всякий случай — ряд только что прошёл почти ровно такое движение.
A10: «Почему T = 3» | B10: Честный ответ: длина цикла решения не измерена и в регламенте не закреплена. Это записано как незакрытый пункт, а не спрятано. Поставьте на «Параметрах» T = 2 или T = 4 — уровень двигается примерно на 1,4–1,5 пп за месяц цикла.
A11: «Почему 90 %, а не 95 или 99» | B11: Это цена ложного отбоя, а не расчёт. При 90 % один ложный сигнал из десяти. Выше — жёлтая опускается и лампа горит почти всегда. Параметр p на листе «Параметры» меняется, z пересчитывается сам. Решение комитета, не наше.
A12: «Где мы сейчас» | B12: Лист «Зоны». Текущая точка 101,50 — жёлтая зона. До лимита 7,13 пп = 1,75 σ. T* = 1,87 месяца: столько остаётся до лимита при доверии 90 %. Красная зона за 36 месяцев загоралась один раз, пробоев не было ни разу.
A13: «А если ничего не менять» | B13: Лист «Расчёт», блок 7. При сохранении уровня 95 % жёлтая линия ложится на 85,97, и выше неё оказывается 31 наблюдение из 36. Светофор с постоянно горящей лампой не является системой раннего предупреждения.
A14: Четыре слабых места — назвать самому | B14: 1) Ряд обрывается на 01.07.2026: на дату записки факт отстаёт на три месяца. 2) T = 3 не измерено. 3) k не константа — за 30 месяцев вырос с 0,779 до 0,875, и уровень, посчитанный по k одной даты, стареет вместе с ним. 4) П. 26 Стратегии о трёх пределах уровня рисков дословно не разобран, поэтому разметка зон — наше предложение, а не соответствие ВНД.
A15: Чего книга не доказывает | B15: Что формулы верны по существу. Она доказывает ровно одно: числа получены из ряда объявленными формулами, а допущения формулы буфера проверены на этом же ряде и не отвергнуты. Верна ли метрика и тот ли это ряд — из воспроизводимости не следует.
A17: Цепочка «риск-ёмкость → риск-аппетит → лимит → допустимый уровень → мера реагирования → контроль» и её фактические разрывы: целиком есть одно звено из шести.

Sheet Ряд
A1: Ряд топ-20: 36 месячных точек, 01.08.2023 — 01.07.2026
A2: Источник: data/top20_monthly_2023_08_2026_07.csv, дамп листа Monthly рабочей книги 08.09.2026 (DECOMPOSITION § 11.7). Колонки A–D — как в выгрузке, E–M — расчёт. С 01.02.2026 регуляторный капитал в выгрузке отсутствует: метрика ведётся только в балансовой базе, поэтому C, E, F и I у последних шести дат пусты. Это не пропуск данных, а следствие смены базы (Г26). Колонки N–S — CoR по КБ/ПБ и по МСБ из того же файла, 36 из 36: в первой сборке листа «Метрики» они были ошибочно взяты из квартального ряда.
A4: Дата | B4: Займ топ-20, млн ₸ | C4: СК регуляторный, млн ₸ | D4: СК балансовый, млн ₸ | E4: coef_reg (доля) | F4: v_reg = coef_reg × 100 | G4: coef_new (доля) | H4: v_new = coef_new × 100 | I4: Разрыв баз: v_new − v_reg | J4: Δ = v_new(t) − v_new(t−1) | K4: ΔСК балансовый, % | L4: ΔЗайм, % | M4: Триггер | N4: cor_kb_pb (доля) | O4: CoR КБ/ПБ, % | P4: Δ CoR КБ/ПБ | Q4: cor_msb (доля) | R4: CoR МСБ, % | S4: Δ CoR МСБ
A5: 2023-08-01 | B5: 323730.9 | C5: 413937.12 | D5: 322505.42 | E5: =IF(C5="","",B5/C5) | F5: =IF(E5="","",E5*100) | G5: =B5/D5 | H5: =G5*100 | I5: =IF(F5="","",H5-F5) | J5: — | K5: — | L5: — | M5: — | N5: 0.022715299 | O5: =N5*100 | P5: — | Q5: -0.00014823711 | R5: =Q5*100 | S5: —
A6: 2023-09-01 | B6: 323218.4 | C6: 422472.24 | D6: 331426.59 | E6: =IF(C6="","",B6/C6) | F6: =IF(E6="","",E6*100) | G6: =B6/D6 | H6: =G6*100 | I6: =IF(F6="","",H6-F6) | J6: =H6-H5 | K6: =(D6-D5)/D5*100 | L6: =(B6-B5)/B5*100 | M6: =IF(AND(K6<=por_sk,L6>=por_zaim),"оба",IF(K6<=por_sk,"СК",IF(L6>=por_zaim,"Займ",""))) | N6: 0.018498312 | O6: =N6*100 | P6: =O6-O5 | Q6: -0.0057911412 | R6: =Q6*100 | S6: =R6-R5
A7: 2023-10-01 | B7: 327285 | C7: 429717.91 | D7: 339057.93 | E7: =IF(C7="","",B7/C7) | F7: =IF(E7="","",E7*100) | G7: =B7/D7 | H7: =G7*100 | I7: =IF(F7="","",H7-F7) | J7: =H7-H6 | K7: =(D7-D6)/D6*100 | L7: =(B7-B6)/B6*100 | M7: =IF(AND(K7<=por_sk,L7>=por_zaim),"оба",IF(K7<=por_sk,"СК",IF(L7>=por_zaim,"Займ",""))) | N7: 0.011475888 | O7: =N7*100 | P7: =O7-O6 | Q7: -0.0078013312 | R7: =Q7*100 | S7: =R7-R6
A8: 2023-11-01 | B8: 338817.1 | C8: 438451.72 | D8: 348167.43 | E8: =IF(C8="","",B8/C8) | F8: =IF(E8="","",E8*100) | G8: =B8/D8 | H8: =G8*100 | I8: =IF(F8="","",H8-F8) | J8: =H8-H7 | K8: =(D8-D7)/D7*100 | L8: =(B8-B7)/B7*100 | M8: =IF(AND(K8<=por_sk,L8>=por_zaim),"оба",IF(K8<=por_sk,"СК",IF(L8>=por_zaim,"Займ",""))) | N8: 0.0021619168 | O8: =N8*100 | P8: =O8-O7 | Q8: -0.01204134 | R8: =Q8*100 | S8: =R8-R7
A9: 2023-12-01 | B9: 343497.7 | C9: 443261.61 | D9: 353304.97 | E9: =IF(C9="","",B9/C9) | F9: =IF(E9="","",E9*100) | G9: =B9/D9 | H9: =G9*100 | I9: =IF(F9="","",H9-F9) | J9: =H9-H8 | K9: =(D9-D8)/D8*100 | L9: =(B9-B8)/B8*100 | M9: =IF(AND(K9<=por_sk,L9>=por_zaim),"оба",IF(K9<=por_sk,"СК",IF(L9>=por_zaim,"Займ",""))) | N9: -0.00076431654 | O9: =N9*100 | P9: =O9-O8 | Q9: -0.010726423 | R9: =Q9*100 | S9: =R9-R8
A10: 2024-01-01 | B10: 372019.3 | C10: 440898.15 | D10: 351291.9 | E10: =IF(C10="","",B10/C10) | F10: =IF(E10="","",E10*100) | G10: =B10/D10 | H10: =G10*100 | I10: =IF(F10="","",H10-F10) | J10: =H10-H9 | K10: =(D10-D9)/D9*100 | L10: =(B10-B9)/B9*100 | M10: =IF(AND(K10<=por_sk,L10>=por_zaim),"оба",IF(K10<=por_sk,"СК",IF(L10>=por_zaim,"Займ",""))) | N10: -0.019343434 | O10: =N10*100 | P10: =O10-O9 | Q10: -0.01082676 | R10: =Q10*100 | S10: =R10-R9
A11: 2024-02-01 | B11: 359821.6 | C11: 453740.46 | D11: 364498.16 | E11: =IF(C11="","",B11/C11) | F11: =IF(E11="","",E11*100) | G11: =B11/D11 | H11: =G11*100 | I11: =IF(F11="","",H11-F11) | J11: =H11-H10 | K11: =(D11-D10)/D10*100 | L11: =(B11-B10)/B10*100 | M11: =IF(AND(K11<=por_sk,L11>=por_zaim),"оба",IF(K11<=por_sk,"СК",IF(L11>=por_zaim,"Займ",""))) | N11: -0.076401161 | O11: =N11*100 | P11: =O11-O10 | Q11: -0.021314956 | R11: =Q11*100 | S11: =R11-R10
A12: 2024-03-01 | B12: 371215.4 | C12: 472963.53 | D12: 384072.88 | E12: =IF(C12="","",B12/C12) | F12: =IF(E12="","",E12*100) | G12: =B12/D12 | H12: =G12*100 | I12: =IF(F12="","",H12-F12) | J12: =H12-H11 | K12: =(D12-D11)/D11*100 | L12: =(B12-B11)/B11*100 | M12: =IF(AND(K12<=por_sk,L12>=por_zaim),"оба",IF(K12<=por_sk,"СК",IF(L12>=por_zaim,"Займ",""))) | N12: -0.047231984 | O12: =N12*100 | P12: =O12-O11 | Q12: -0.0051275576 | R12: =Q12*100 | S12: =R12-R11
A13: 2024-04-01 | B13: 363473 | C13: 484711.53 | D13: 396208.88 | E13: =IF(C13="","",B13/C13) | F13: =IF(E13="","",E13*100) | G13: =B13/D13 | H13: =G13*100 | I13: =IF(F13="","",H13-F13) | J13: =H13-H12 | K13: =(D13-D12)/D12*100 | L13: =(B13-B12)/B12*100 | M13: =IF(AND(K13<=por_sk,L13>=por_zaim),"оба",IF(K13<=por_sk,"СК",IF(L13>=por_zaim,"Займ",""))) | N13: -0.039429405 | O13: =N13*100 | P13: =O13-O12 | Q13: -0.010741815 | R13: =Q13*100 | S13: =R13-R12
A14: 2024-05-01 | B14: 357665.7 | C14: 489303.47 | D14: 401188.39 | E14: =IF(C14="","",B14/C14) | F14: =IF(E14="","",E14*100) | G14: =B14/D14 | H14: =G14*100 | I14: =IF(F14="","",H14-F14) | J14: =H14-H13 | K14: =(D14-D13)/D13*100 | L14: =(B14-B13)/B13*100 | M14: =IF(AND(K14<=por_sk,L14>=por_zaim),"оба",IF(K14<=por_sk,"СК",IF(L14>=por_zaim,"Займ",""))) | N14: -0.033388896 | O14: =N14*100 | P14: =O14-O13 | Q14: -0.0071952721 | R14: =Q14*100 | S14: =R14-R13
A15: 2024-06-01 | B15: 360756.5 | C15: 491481.95 | D15: 403780.01 | E15: =IF(C15="","",B15/C15) | F15: =IF(E15="","",E15*100) | G15: =B15/D15 | H15: =G15*100 | I15: =IF(F15="","",H15-F15) | J15: =H15-H14 | K15: =(D15-D14)/D14*100 | L15: =(B15-B14)/B14*100 | M15: =IF(AND(K15<=por_sk,L15>=por_zaim),"оба",IF(K15<=por_sk,"СК",IF(L15>=por_zaim,"Займ",""))) | N15: -0.024675437 | O15: =N15*100 | P15: =O15-O14 | Q15: -0.0065286648 | R15: =Q15*100 | S15: =R15-R14
A16: 2024-07-01 | B16: 362413.9 | C16: 492537.19 | D16: 405247.49 | E16: =IF(C16="","",B16/C16) | F16: =IF(E16="","",E16*100) | G16: =B16/D16 | H16: =G16*100 | I16: =IF(F16="","",H16-F16) | J16: =H16-H15 | K16: =(D16-D15)/D15*100 | L16: =(B16-B15)/B15*100 | M16: =IF(AND(K16<=por_sk,L16>=por_zaim),"оба",IF(K16<=por_sk,"СК",IF(L16>=por_zaim,"Займ",""))) | N16: -0.022446194 | O16: =N16*100 | P16: =O16-O15 | Q16: -0.0038854969 | R16: =Q16*100 | S16: =R16-R15
A17: 2024-08-01 | B17: 358163.4 | C17: 504710.47 | D17: 417859.74 | E17: =IF(C17="","",B17/C17) | F17: =IF(E17="","",E17*100) | G17: =B17/D17 | H17: =G17*100 | I17: =IF(F17="","",H17-F17) | J17: =H17-H16 | K17: =(D17-D16)/D16*100 | L17: =(B17-B16)/B16*100 | M17: =IF(AND(K17<=por_sk,L17>=por_zaim),"оба",IF(K17<=por_sk,"СК",IF(L17>=por_zaim,"Займ",""))) | N17: -0.021509859 | O17: =N17*100 | P17: =O17-O16 | Q17: -0.0044458864 | R17: =Q17*100 | S17: =R17-R16
... A34: 2026-01-01 | B34: 421717.7 | C34: 503086.11 | D34: 439961.27 | E34: =IF(C34="","",B34/C34) | F34: =IF(E34="","",E34*100) | G34: =B34/D34 | H34: =G34*100 | I34: =IF(F34="","",H34-F34) | J34: =H34-H33 | K34: =(D34-D33)/D33*100 | L34: =(B34-B33)/B33*100 | M34: =IF(AND(K34<=por_sk,L34>=por_zaim),"оба",IF(K34<=por_sk,"СК",IF(L34>=por_zaim,"Займ",""))) | N34: -0.010006426 | O34: =N34*100 | P34: =O34-O33 | Q34: -0.009844636 | R34: =Q34*100 | S34: =R34-R33
A35: 2026-02-01 | B35: 393670.5 | D35: 440063.85 | E35: =IF(C35="","",B35/C35) | F35: =IF(E35="","",E35*100) | G35: =B35/D35 | H35: =G35*100 | I35: =IF(F35="","",H35-F35) | J35: =H35-H34 | K35: =(D35-D34)/D34*100 | L35: =(B35-B34)/B34*100 | M35: =IF(AND(K35<=por_sk,L35>=por_zaim),"оба",IF(K35<=por_sk,"СК",IF(L35>=por_zaim,"Займ",""))) | N35: 0.0062116289 | O35: =N35*100 | P35: =O35-O34 | Q35: 0.0047314406 | R35: =Q35*100 | S35: =R35-R34
A36: 2026-03-01 | B36: 395281.7 | D36: 449623.8 | E36: =IF(C36="","",B36/C36) | F36: =IF(E36="","",E36*100) | G36: =B36/D36 | H36: =G36*100 | I36: =IF(F36="","",H36-F36) | J36: =H36-H35 | K36: =(D36-D35)/D35*100 | L36: =(B36-B35)/B35*100 | M36: =IF(AND(K36<=por_sk,L36>=por_zaim),"оба",IF(K36<=por_sk,"СК",IF(L36>=por_zaim,"Займ",""))) | N36: 0.0011747746 | O36: =N36*100 | P36: =O36-O35 | Q36: 0.0029763559 | R36: =Q36*100 | S36: =R36-R35
A37: 2026-04-01 | B37: 416607.1 | D37: 446679.83 | E37: =IF(C37="","",B37/C37) | F37: =IF(E37="","",E37*100) | G37: =B37/D37 | H37: =G37*100 | I37: =IF(F37="","",H37-F37) | J37: =H37-H36 | K37: =(D37-D36)/D36*100 | L37: =(B37-B36)/B36*100 | M37: =IF(AND(K37<=por_sk,L37>=por_zaim),"оба",IF(K37<=por_sk,"СК",IF(L37>=por_zaim,"Займ",""))) | N37: -0.0034830032 | O37: =N37*100 | P37: =O37-O36 | Q37: 0.0019644136 | R37: =Q37*100 | S37: =R37-R36
A38: 2026-05-01 | B38: 439754.5 | D38: 446857.15 | E38: =IF(C38="","",B38/C38) | F38: =IF(E38="","",E38*100) | G38: =B38/D38 | H38: =G38*100 | I38: =IF(F38="","",H38-F38) | J38: =H38-H37 | K38: =(D38-D37)/D37*100 | L38: =(B38-B37)/B37*100 | M38: =IF(AND(K38<=por_sk,L38>=por_zaim),"оба",IF(K38<=por_sk,"СК",IF(L38>=por_zaim,"Займ",""))) | N38: -0.0033998343 | O38: =N38*100 | P38: =O38-O37 | Q38: 0.0019142856 | R38: =Q38*100 | S38: =R38-R37
A39: 2026-06-01 | B39: 444048.8 | D39: 440316.78 | E39: =IF(C39="","",B39/C39) | F39: =IF(E39="","",E39*100) | G39: =B39/D39 | H39: =G39*100 | I39: =IF(F39="","",H39-F39) | J39: =H39-H38 | K39: =(D39-D38)/D38*100 | L39: =(B39-B38)/B38*100 | M39: =IF(AND(K39<=por_sk,L39>=por_zaim),"оба",IF(K39<=por_sk,"СК",IF(L39>=por_zaim,"Займ",""))) | N39: 0.0037743682 | O39: =N39*100 | P39: =O39-O38 | Q39: 0.0033711825 | R39: =Q39*100 | S39: =R39-R38
A40: 2026-07-01 | B40: 448999.7 | D40: 442346.33 | E40: =IF(C40="","",B40/C40) | F40: =IF(E40="","",E40*100) | G40: =B40/D40 | H40: =G40*100 | I40: =IF(F40="","",H40-F40) | J40: =H40-H39 | K40: =(D40-D39)/D39*100 | L40: =(B40-B39)/B39*100 | M40: =IF(AND(K40<=por_sk,L40>=por_zaim),"оба",IF(K40<=por_sk,"СК",IF(L40>=por_zaim,"Займ",""))) | N40: -0.0026735176 | O40: =N40*100 | P40: =O40-O39 | Q40: 0.0026665901 | R40: =Q40*100 | S40: =R40-R39
A42: Колонка I — разрыв двух баз на одну дату, а не движение во времени. Через неё видно, что k не постоянен: разрыв сузился с 22,2 пп в 08.2023 до 12,0 пп в 01.2026. Уровень L = L_рег / k, посчитанный по k одной даты, стареет вместе с k — открытый вопрос к запросу данных, не свойство расчёта.
A44: Уровень не ограничивал показатель 8 лет 6 месяцев: шесть эпизодов превышения относительно уровня, действовавшего на дату.

Sheet Параметры
A1: Параметры расчёта
A2: Всё, что не выводится из ряда. Меняется здесь — пересчитывается везде.
A4: Параметр | B4: Обозначение | C4: Значение | D4: Формула | E4: Откуда
A5: Доверие для буфера | B5: p | C5: 0.9 | D5: ввод | E5: Доля T-месячных движений, которые буфер обязан накрыть. 0,90 означает один ложный отбой из десяти. Это РЕШЕНИЕ комитета о цене ложного сигнала, а не расчётная величина: выше p — жёлтая ниже, лампа горит чаще
A6: Квантиль нормального | B6: z(p) | C6: =NORMSINV(C5) | D6: NORMSINV(p) | E6: Вычисляется из p, не вбивается. По-русски функция называется НОРМСТОБР
A7: Отношение баз капитала | B7: k (Г26) | C7: =Ряд!D34/Ряд!C34 | D7: Ряд!D34/Ряд!C34 | E7: СК_балансовый / СК_регуляторный на 01.01.2026 — последняя дата, где есть обе базы. Находка Г26: с 01.01.2026 знаменатель метрики сменил базу, уровень при этом не пересматривался. ВНИМАНИЕ: k не константа, см. колонку I листа «Ряд»
A8: Уровень в регуляторной базе | B8: L_рег | C8: 95 | D8: ввод | E8: Действующий уровень риск-аппетита по топ-20. Приложение № 3 к Политике (VND-02). История уровня: 250 % → 95 %, см. data/top20_limit_history.csv
A9: Длина цикла реагирования, мес. | B9: T | C9: 3 | D9: ввод | E9: ДОПУЩЕНИЕ, не измеренная величина. Пока длина цикла не закреплена в регламенте, метод H держится на ней со слов — DISCLOSURE § 6
A10: Порог триггера по капиталу, % | B10: порог ΔСК | C10: -3 | D10: ввод | E10: Месячное падение СК, при котором наблюдение ускоряется независимо от зоны
A11: Порог триггера по портфелю, % | B11: порог ΔЗайм | C11: 5 | D11: ввод | E11: Месячный рост задолженности топ-20, при котором наблюдение ускоряется
A13: Из семи параметров вычисляются два: z из p и k из ряда. Остальные пять — чьи-то решения, и у каждого должен быть автор. У L_рег он есть (Приложение № 3), у T и двух порогов — нет. T = 3 единственный без внешнего источника: поставьте другое число в C9 — вся книга пересчитается, и станет видно, что требуемый уровень меняется на 1,4–1,5 пп за каждый месяц цикла.

Sheet Расчёт
A1: Расчётный лист: формула, вход, результат
A2: Колонка D считается формулой из листов «Ряд» и «Параметры». Колонка E — то, что напечатано в DECOMPOSITION § 11.10 и DISCLOSURE § 2. Колонка G должна быть «да» во всех строках: иначе опубликованное число разошлось с расчётом.
A4: Показатель | B4: Формула словами | C4: Формула в этой книге | D4: Значение | E4: Где напечатано
A5: 1. База: что даёт сам ряд
A6: σ_Δ — с.к.о. месячных приростов | B6: выборочное с.к.о. (n−1) по всем 35 приростам | C6: STDEV(d) | D6: =STDEV(d) | E6: DISCLOSURE § 2.1
A7: σ уровней (метод М1) | B7: выборочное с.к.о. самих значений ряда, не приростов | C7: STDEV(v) | D7: =STDEV(v) | E7: DISCLOSURE Р-Д1
A8: Текущая точка, 01.07.2026 | B8: последнее значение ряда | C8: Ряд!H40 | D8: =Ряд!H40 | E8: DISCLOSURE § 2.1
A9: Максимум ряда, 01.2024 | B9: наибольшее значение ряда | C9: MAX(v) | D9: =MAX(v) | E9: DISCLOSURE § 2.1
A10: Число точек | B10: сколько наблюдений в ряде | C10: COUNT(v) | D10: =COUNT(v) | E10: DISCLOSURE § 1
A11: 2. Уровень
A12: L — уровень в балансовой базе | B12: действующий уровень 95 %, пересчитанный под балансовый капитал: L_рег / k | C12: L_reg/k_G26 | D12: =L_reg/k_G26 | E12: DISCLOSURE § 2.2
A13: X — граница L − M(3) в процентах лимита | B13: 1 − M(T)/L: доля лимита, на которой стоит жёлтая линия | C13: (1-D24/D12)*100 | D13: =(1-D24/D12)*100 | E13: новое, 14.09.2026
A14: Это одна величина в двух системах измерения, а не два разных лимита. Фраза «пробит лимит 95 % по балансовому капиталу» — категориальная ошибка: числитель берётся из одной базы, знаменатель из другой. Значение 108,6304 стоит на k, посчитанном из ряда; в DISCLOSURE до 14.09.2026 печаталось 108,6298 — та же величина при k, округлённом до пяти знаков.
A15: 3. Запас на реагирование M(T) = z(p) · σ_Δ · √T и границы L − M(T)
A16: Запас M(T) при T = 1 | B16: z(p) × σ_Δ × корень из T | C16: z_p*D6*SQRT(1) | D16: =z_p*D6*SQRT(1) | E16: DISCLOSURE § 2.3
A17: Граница L − M(T) при T = 1 | B17: L − M(T) | C17: D12-D16 | D17: =D12-D16 | E17: DISCLOSURE § 2.3
A18: Наблюдений выше границы, T = 1 | B18: сколько точек ряда не ниже этой границы | C18: COUNTIF(v,">="&D17) | D18: =COUNTIF(v,">="&D17) | E18: DISCLOSURE § 2.3, Р-Д3
A19: Доля времени выше границы, T = 1 | B19: их доля от 36 наблюдений | C19: COUNTIF(v,">="&D17)/COUNT(v)*100 | D19: =COUNTIF(v,">="&D17)/COUNT(v)*100 | E19: DISCLOSURE § 2.3, Р-Д3
A20: Запас M(T) при T = 2 | B20: z(p) × σ_Δ × корень из T | C20: z_p*D6*SQRT(2) | D20: =z_p*D6*SQRT(2) | E20: DISCLOSURE § 2.3
A21: Граница L − M(T) при T = 2 | B21: L − M(T) | C21: D12-D20 | D21: =D12-D20 | E21: DISCLOSURE § 2.3
A22: Наблюдений выше границы, T = 2 | B22: сколько точек ряда не ниже этой границы | C22: COUNTIF(v,">="&D21) | D22: =COUNTIF(v,">="&D21) | E22: DISCLOSURE § 2.3, Р-Д3
A23: Доля времени выше границы, T = 2 | B23: их доля от 36 наблюдений | C23: COUNTIF(v,">="&D21)/COUNT(v)*100 | D23: =COUNTIF(v,">="&D21)/COUNT(v)*100 | E23: DISCLOSURE § 2.3, Р-Д3
A24: Запас M(T) при T = 3 | B24: z(p) × σ_Δ × корень из T | C24: z_p*D6*SQRT(3) | D24: =z_p*D6*SQRT(3) | E24: DISCLOSURE § 2.3
A25: Граница L − M(T) при T = 3 | B25: L − M(T) | C25: D12-D24 | D25: =D12-D24 | E25: DISCLOSURE § 2.3
A26: Наблюдений выше границы, T = 3 | B26: сколько точек ряда не ниже этой границы | C26: COUNTIF(v,">="&D25) | D26: =COUNTIF(v,">="&D25) | E26: DISCLOSURE § 2.3, Р-Д3
A27: Доля времени выше границы, T = 3 | B27: их доля от 36 наблюдений | C27: COUNTIF(v,">="&D25)/COUNT(v)*100 | D27: =COUNTIF(v,">="&D25)/COUNT(v)*100 | E27: DISCLOSURE § 2.3, Р-Д3
A28: Запас M(T) при T = 4 | B28: z(p) × σ_Δ × корень из T | C28: z_p*D6*SQRT(4) | D28: =z_p*D6*SQRT(4) | E28: DISCLOSURE § 2.3
A29: Граница L − M(T) при T = 4 | B29: L − M(T) | C29: D12-D28 | D29: =D12-D28 | E29: DISCLOSURE § 2.3
A30: Наблюдений выше границы, T = 4 | B30: сколько точек ряда не ниже этой границы | C30: COUNTIF(v,">="&D29) | D30: =COUNTIF(v,">="&D29) | E30: DISCLOSURE § 2.3, Р-Д3
A31: Доля времени выше границы, T = 4 | B31: их доля от 36 наблюдений | C31: COUNTIF(v,">="&D29)/COUNT(v)*100 | D31: =COUNTIF(v,">="&D29)/COUNT(v)*100 | E31: DISCLOSURE § 2.3, Р-Д3
A32: Р-Д3: доля в процентах от 36 наблюдений читается точнее, чем есть. 2,8 % — это одно наблюдение, 11,1 % — четыре. На комитете доля называется только вместе с числом наблюдений, поэтому строка «Наблюдений» стоит выше строки «Доля», а не под ней. Обоснование самой формулы M(T) — на листе «Обоснование M(T)»; разметка зон по этим границам — на листе «Зоны».
A33: 4. Квантили ряда (метод C). Линейная интерполяция между порядковыми статистиками
A34: Квантиль 85 % | B34: значение, ниже которого лежит 85 % ряда | C34: PERCENTILE(v,0.85) | D34: =PERCENTILE(v,0.85) | E34: DISCLOSURE § 2.5
A35: Квантиль 90 % | B35: значение, ниже которого лежит 90 % ряда | C35: PERCENTILE(v,0.90) | D35: =PERCENTILE(v,0.90) | E35: DISCLOSURE § 2.5
A36: Квантиль 95 % | B36: значение, ниже которого лежит 95 % ряда | C36: PERCENTILE(v,0.95) | D36: =PERCENTILE(v,0.95) | E36: DISCLOSURE § 2.5
A37: 5. Два независимых пути к одному уровню
A38: Метод H: квантиль 90 % + запас T = 3 | B38: квантиль₉₀(v) + M(3) | C38: D35+D24 | D38: =D35+D24 | E38: DISCLOSURE § 2.4
A39: Расхождение двух путей | B39: L (пересчёт базы) − H (цикл решения) | C39: D12-D38 | D39: =D12-D38 | E39: DISCLOSURE § 2.4
A40: Главный довод против упрёка «уровень подогнан под факт»: пути не связаны по построению. Первый смотрит на отношение баз капитала, второй — на распределение ряда и длину процесса. Сходятся на 0,05 пп.
A41: 6. Производные метрики
...

Sheet Обоснование M(T)
A1: Обоснование формулы M(T) = z(p) · σ_Δ · √T
A2: Формула держится на трёх допущениях: приросты независимы (отсюда √T), распределение суммы близко к нормальному (отсюда z), дрейфа нет. Ниже каждое проверено на нашем же ряде. Колонки J–N — служебные: T-месячные изменения, по которым считаются проверки.
A4: Проверка | B4: Что именно проверяется | C4: Формула в этой книге | D4: Значение | E4: Как читать | G4: Изменение за 1 мес. | H4: Изменение за 2 мес. | I4: Изменение за 3 мес. | J4: Изменение за 4 мес. | K4: Изменение за 6 мес.
A5: 1. Независимость приростов — единственное, на чём держится √T | G5: =Ряд!H6-Ряд!H5 | H5: =Ряд!H7-Ряд!H5 | I5: =Ряд!H8-Ряд!H5 | J5: =Ряд!H9-Ряд!H5 | K5: =Ряд!H11-Ряд!H5
A6: Автокорреляция лага 1 | B6: связь прироста с предыдущим приростом | C6: CORREL(Ряд!J7:J40,Ряд!J6:J39) | D6: =CORREL(Ряд!J7:J40,Ряд!J6:J39) | E6: новое, 14.09.2026 | G6: =Ряд!H7-Ряд!H6 | H6: =Ряд!H8-Ряд!H6 | I6: =Ряд!H9-Ряд!H6 | J6: =Ряд!H10-Ряд!H6 | K6: =Ряд!H12-Ряд!H6
A7: Порог значимости 2/√n | B7: выше этого значения автокорреляцию нельзя считать шумом | C7: 2/SQRT(COUNT(d)) | D7: =2/SQRT(COUNT(d)) | E7: новое | G7: =Ряд!H8-Ряд!H7 | H7: =Ряд!H9-Ряд!H7 | I7: =Ряд!H10-Ряд!H7 | J7: =Ряд!H11-Ряд!H7 | K7: =Ряд!H13-Ряд!H7
A8: |−0,083| против порога 0,338 — свидетельств против независимости нет. Это НЕ доказательство независимости: при 35 наблюдениях тест почти лишён мощности. Сказать об этом надо самим, иначе скажет оппонент. | G8: =Ряд!H9-Ряд!H8 | H8: =Ряд!H10-Ряд!H8 | I8: =Ряд!H11-Ряд!H8 | J8: =Ряд!H12-Ряд!H8 | K8: =Ряд!H14-Ряд!H8
A9: Фактическое с.к.о. изменений за 1 мес. | B9: разброс реальных 1-месячных изменений ряда | C9: STDEV($G$5:$G$39) | D9: =STDEV($G$5:$G$39) | E9: новое | G9: =Ряд!H10-Ряд!H9 | H9: =Ряд!H11-Ряд!H9 | I9: =Ряд!H12-Ряд!H9 | J9: =Ряд!H13-Ряд!H9 | K9: =Ряд!H15-Ряд!H9
A10: Отношение факт / модель при T = 1 | B10: во сколько раз реальный разброс отличается от σ_Δ·√1 | C10: D9/('Расчёт'!D6*SQRT(1)) | D10: =D9/('Расчёт'!D6*SQRT(1)) | E10: новое | G10: =Ряд!H11-Ряд!H10 | H10: =Ряд!H12-Ряд!H10 | I10: =Ряд!H13-Ряд!H10 | J10: =Ряд!H14-Ряд!H10 | K10: =Ряд!H16-Ряд!H10
A11: Фактическое с.к.о. изменений за 2 мес. | B11: разброс реальных 2-месячных изменений ряда | C11: STDEV($H$5:$H$38) | D11: =STDEV($H$5:$H$38) | E11: новое | G11: =Ряд!H12-Ряд!H11 | H11: =Ряд!H13-Ряд!H11 | I11: =Ряд!H14-Ряд!H11 | J11: =Ряд!H15-Ряд!H11 | K11: =Ряд!H17-Ряд!H11
A12: Отношение факт / модель при T = 2 | B12: во сколько раз реальный разброс отличается от σ_Δ·√2 | C12: D11/('Расчёт'!D6*SQRT(2)) | D12: =D11/('Расчёт'!D6*SQRT(2)) | E12: новое | G12: =Ряд!H13-Ряд!H12 | H12: =Ряд!H14-Ряд!H12 | I12: =Ряд!H15-Ряд!H12 | J12: =Ряд!H16-Ряд!H12 | K12: =Ряд!H18-Ряд!H12
A13: Фактическое с.к.о. изменений за 3 мес. | B13: разброс реальных 3-месячных изменений ряда | C13: STDEV($I$5:$I$37) | D13: =STDEV($I$5:$I$37) | E13: новое | G13: =Ряд!H14-Ряд!H13 | H13: =Ряд!H15-Ряд!H13 | I13: =Ряд!H16-Ряд!H13 | J13: =Ряд!H17-Ряд!H13 | K13: =Ряд!H19-Ряд!H13
A14: Отношение факт / модель при T = 3 | B14: во сколько раз реальный разброс отличается от σ_Δ·√3 | C14: D13/('Расчёт'!D6*SQRT(3)) | D14: =D13/('Расчёт'!D6*SQRT(3)) | E14: новое | G14: =Ряд!H15-Ряд!H14 | H14: =Ряд!H16-Ряд!H14 | I14: =Ряд!H17-Ряд!H14 | J14: =Ряд!H18-Ряд!H14 | K14: =Ряд!H20-Ряд!H14
A15: Фактическое с.к.о. изменений за 4 мес. | B15: разброс реальных 4-месячных изменений ряда | C15: STDEV($J$5:$J$36) | D15: =STDEV($J$5:$J$36) | E15: новое | G15: =Ряд!H16-Ряд!H15 | H15: =Ряд!H17-Ряд!H15 | I15: =Ряд!H18-Ряд!H15 | J15: =Ряд!H19-Ряд!H15 | K15: =Ряд!H21-Ряд!H15
A16: Отношение факт / модель при T = 4 | B16: во сколько раз реальный разброс отличается от σ_Δ·√4 | C16: D15/('Расчёт'!D6*SQRT(4)) | D16: =D15/('Расчёт'!D6*SQRT(4)) | E16: новое | G16: =Ряд!H17-Ряд!H16 | H16: =Ряд!H18-Ряд!H16 | I16: =Ряд!H19-Ряд!H16 | J16: =Ряд!H20-Ряд!H16 | K16: =Ряд!H22-Ряд!H16
A17: Фактическое с.к.о. изменений за 6 мес. | B17: разброс реальных 6-месячных изменений ряда | C17: STDEV($K$5:$K$34) | D17: =STDEV($K$5:$K$34) | E17: новое | G17: =Ряд!H18-Ряд!H17 | H17: =Ряд!H19-Ряд!H17 | I17: =Ряд!H20-Ряд!H17 | J17: =Ряд!H21-Ряд!H17 | K17: =Ряд!H23-Ряд!H17
A18: Отношение факт / модель при T = 6 | B18: во сколько раз реальный разброс отличается от σ_Δ·√6 | C18: D17/('Расчёт'!D6*SQRT(6)) | D18: =D17/('Расчёт'!D6*SQRT(6)) | E18: новое | G18: =Ряд!H19-Ряд!H18 | H18: =Ряд!H20-Ряд!H18 | I18: =Ряд!H21-Ряд!H18 | J18: =Ряд!H22-Ряд!H18 | K18: =Ряд!H24-Ряд!H18
A19: Отношение ниже единицы означает, что √T ЗАВЫШАЕТ разброс: ряд слегка возвращается к среднему. На T = 3 завышение 9 %, на T = 6 — 23 %. Для буфера это ошибка в безопасную сторону — жёлтая линия ниже, предупреждение раньше. Оговорка: окна перекрываются, поэтому это оценка, а не точное измерение. | G19: =Ряд!H20-Ряд!H19 | H19: =Ряд!H21-Ряд!H19 | I19: =Ряд!H22-Ряд!H19 | J19: =Ряд!H23-Ряд!H19 | K19: =Ряд!H25-Ряд!H19
A20: 2. Нормальность — и почему нужна не та, о которой спрашивают | G20: =Ряд!H21-Ряд!H20 | H20: =Ряд!H22-Ряд!H20 | I20: =Ряд!H23-Ряд!H20 | J20: =Ряд!H24-Ряд!H20 | K20: =Ряд!H26-Ряд!H20
A21: Асимметрия приростов | B21: скошенность месячных приростов: третий момент / σ³ | C21: (SUMPRODUCT((d-AVERAGE(d))^3)/COUNT(d))/(SUMPRODUCT((d-AVERAGE(d))^2)/COUNT(d))^1.5 | D21: =(SUMPRODUCT((d-AVERAGE(d))^3)/COUNT(d))/(SUMPRODUCT((d-AVERAGE(d))^2)/COUNT(d))^1.5 | E21: новое | G21: =Ряд!H22-Ряд!H21 | H21: =Ряд!H23-Ряд!H21 | I21: =Ряд!H24-Ряд!H21 | J21: =Ряд!H25-Ряд!H21 | K21: =Ряд!H27-Ряд!H21
A22: Избыточный эксцесс приростов | B22: толщина хвостов приростов: четвёртый момент / σ⁴ − 3 | C22: (SUMPRODUCT((d-AVERAGE(d))^4)/COUNT(d))/(SUMPRODUCT((d-AVERAGE(d))^2)/COUNT(d))^2-3 | D22: =(SUMPRODUCT((d-AVERAGE(d))^4)/COUNT(d))/(SUMPRODUCT((d-AVERAGE(d))^2)/COUNT(d))^2-3 | E22: новое | G22: =Ряд!H23-Ряд!H22 | H22: =Ряд!H24-Ряд!H22 | I22: =Ряд!H25-Ряд!H22 | J22: =Ряд!H26-Ряд!H22 | K22: =Ряд!H28-Ряд!H22
A23: Жарк–Бера по приростам | B23: сводный тест нормальности: n/6 × (g1² + g2²/4) | C23: COUNT(d)/6*(D21^2+D22^2/4) | D23: =COUNT(d)/6*(D21^2+D22^2/4) | E23: новое | G23: =Ряд!H24-Ряд!H23 | H23: =Ряд!H25-Ряд!H23 | I23: =Ряд!H26-Ряд!H23 | J23: =Ряд!H27-Ряд!H23 | K23: =Ряд!H29-Ряд!H23
A24: Критическое значение 5 % | B24: порог хи-квадрат с 2 степенями свободы; выше него нормальность отвергается | C24: 5.991 | D24: =5.991 | E24: статистическая таблица | G24: =Ряд!H25-Ряд!H24 | H24: =Ряд!H26-Ряд!H24 | I24: =Ряд!H27-Ряд!H24 | J24: =Ряд!H28-Ряд!H24 | K24: =Ряд!H30-Ряд!H24
A25: Асимметрия 3-месячных изменений | B25: скошенность того, к чему буфер реально применяется | C25: (SUMPRODUCT(($I$5:$I$37-AVERAGE($I$5:$I$37))^3)/COUNT($I$5:$I$37))/(SUMPRODUCT(($I$5:$I$37-AVERAGE($I$5:$I$37))^2)/COUNT($I$5:$I$37))^1.5 | D25: =(SUMPRODUCT(($I$5:$I$37-AVERAGE($I$5:$I$37))^3)/COUNT($I$5:$I$37))/(SUMPRODUCT(($I$5:$I$37-AVERAGE($I$5:$I$37))^2)/COUNT($I$5:$I$37))^1.5 | E25: новое | G25: =Ряд!H26-Ряд!H25 | H25: =Ряд!H27-Ряд!H25 | I25: =Ряд!H28-Ряд!H25 | J25: =Ряд!H29-Ряд!H25 | K25: =Ряд!H31-Ряд!H25
A26: Избыточный эксцесс 3-месячных изменений | B26: толщина хвостов трёхмесячной суммы | C26: (SUMPRODUCT(($I$5:$I$37-AVERAGE($I$5:$I$37))^4)/COUNT($I$5:$I$37))/(SUMPRODUCT(($I$5:$I$37-AVERAGE($I$5:$I$37))^2)/COUNT($I$5:$I$37))^2-3 | D26: =(SUMPRODUCT(($I$5:$I$37-AVERAGE($I$5:$I$37))^4)/COUNT($I$5:$I$37))/(SUMPRODUCT(($I$5:$I$37-AVERAGE($I$5:$I$37))^2)/COUNT($I$5:$I$37))^2-3 | E26: новое | G26: =Ряд!H27-Ряд!H26 | H26: =Ряд!H28-Ряд!H26 | I26: =Ряд!H29-Ряд!H26 | J26: =Ряд!H30-Ряд!H26 | K26: =Ряд!H32-Ряд!H26
A27: Жарк–Бера по 3-месячным изменениям | B27: тот же тест на трёхмесячной сумме | C27: COUNT($I$5:$I$37)/6*(D25^2+D26^2/4) | D27: =COUNT($I$5:$I$37)/6*(D25^2+D26^2/4) | E27: новое | G27: =Ряд!H28-Ряд!H27 | H27: =Ряд!H29-Ряд!H27 | I27: =Ряд!H30-Ряд!H27 | J27: =Ряд!H31-Ряд!H27 | K27: =Ряд!H33-Ряд!H27
A28: Что предсказывает ЦПТ | B28: асимметрия суммы трёх независимых = g1 / √3 | C28: D21/SQRT(3) | D28: =D21/SQRT(3) | E28: новое | G28: =Ряд!H29-Ряд!H28 | H28: =Ряд!H30-Ряд!H28 | I28: =Ряд!H31-Ряд!H28 | J28: =Ряд!H32-Ряд!H28 | K28: =Ряд!H34-Ряд!H28
A29: Главный довод: буфер применяется не к приростам, а к их трёхмесячной СУММЕ. У приростов асимметрия 0,67 — заметная. У трёхмесячной суммы 0,04, то есть она исчезла, и даже быстрее, чем требовала ЦПТ (0,39). Жарк–Бера 2,70 против критических 5,99 — нормальность не отвергается даже на приростах. И третье: z(0,90) = 1,28 лежит в теле распределения, а не в хвосте; ошибки нормальности бьют на 99 % и 99,9 %, а не на 90 %. | G29: =Ряд!H30-Ряд!H29 | H29: =Ряд!H31-Ряд!H29 | I29: =Ряд!H32-Ряд!H29 | J29: =Ряд!H33-Ряд!H29 | K29: =Ряд!H35-Ряд!H29
A30: 3. Буфер M(3) четырьмя независимыми способами | G30: =Ряд!H31-Ряд!H30 | H30: =Ряд!H32-Ряд!H30 | I30: =Ряд!H33-Ряд!H30 | J30: =Ряд!H34-Ряд!H30 | K30: =Ряд!H36-Ряд!H30
A31: Нормальная модель z·σ_Δ·√3 | B31: то, что стоит в расчёте | C31: z_p*'Расчёт'!D6*SQRT(3) | D31: =z_p*'Расчёт'!D6*SQRT(3) | E31: DISCLOSURE § 2.3 | G31: =Ряд!H32-Ряд!H31 | H31: =Ряд!H33-Ряд!H31 | I31: =Ряд!H34-Ряд!H31 | J31: =Ряд!H35-Ряд!H31 | K31: =Ряд!H37-Ряд!H31
A32: Эмпирический 90-й процентиль | B32: 90 % реальных 3-месячных изменений не превысили эту величину | C32: PERCENTILE($I$5:$I$37,p_conf) | D32: =PERCENTILE($I$5:$I$37,p_conf) | E32: новое | G32: =Ряд!H33-Ряд!H32 | H32: =Ряд!H34-Ряд!H32 | I32: =Ряд!H35-Ряд!H32 | J32: =Ряд!H36-Ряд!H32 | K32: =Ряд!H38-Ряд!H32
A33: Корниш–Фишер | B33: нормальный квантиль с поправкой на асимметрию и эксцесс суммы | C33: (z_p+(z_p^2-1)/6*D21/SQRT(3)+(z_p^3-3*z_p)/24*D22/3-(2*z_p^3-5*z_p)/36*(D21/SQRT(3))^2)*'Расчёт'!D6*SQRT(3) | D33: =(z_p+(z_p^2-1)/6*D21/SQRT(3)+(z_p^3-3*z_p)/24*D22/3-(2*z_p^3-5*z_p)/36*(D21/SQRT(3))^2)*'Расчёт'!D6*SQRT(3) | E33: новое | G33: =Ряд!H34-Ряд!H33 | H33: =Ряд!H35-Ряд!H33 | I33: =Ряд!H36-Ряд!H33 | J33: =Ряд!H37-Ряд!H33 | K33: =Ряд!H39-Ряд!H33
A34: Разброс трёх способов, % | B34: насколько максимальный ответ выше минимального | C34: MAX(D31,D32,D33)/MIN(D31,D32,D33)*100-100 | D34: =MAX(D31,D32,D33)/MIN(D31,D32,D33)*100-100 | E34: новое | G34: =Ряд!H35-Ряд!H34 | H34: =Ряд!H36-Ряд!H34 | I34: =Ряд!H37-Ряд!H34 | J34: =Ряд!H38-Ряд!H34 | K34: =Ряд!H40-Ряд!H34
A35: Стандартная ошибка самой σ_Δ | B35: точность оценки σ по 35 наблюдениям: σ / √(2(n−1)) | C35: 'Расчёт'!D6/SQRT(2*(COUNT(d)-1)) | D35: ='Расчёт'!D6/SQRT(2*(COUNT(d)-1)) | E35: новое | G35: =Ряд!H36-Ряд!H35 | H35: =Ряд!H37-Ряд!H35 | I35: =Ряд!H38-Ряд!H35 | J35: =Ряд!H39-Ряд!H35
A36: Она же в единицах M(3) | B36: z · SE(σ) · √3 — неопределённость буфера | C36: z_p*D35*SQRT(3) | D36: =z_p*D35*SQRT(3) | E36: новое | G36: =Ряд!H37-Ряд!H36 | H36: =Ряд!H38-Ряд!H36 | I36: =Ряд!H39-Ряд!H36 | J36: =Ряд!H40-Ряд!H36
A37: Все три непараметрических способа дают буфер ВЫШЕ нормальной модели, разброс 3,6 %. Направление систематическое: нормальная модель тонковата примерно на 0,33 пп. Поправка сознательно не вносится — собственная погрешность σ_Δ равна ±1,09 пп, то есть втрое больше смещения. Но записано это должно быть явно: ровно за молчание о выборе σ мы критикуем метод B в Р-Д1. Четвёртый способ — бутстрап 200 тыс. сумм трёх случайно взятых приростов — даёт 9,3688; в Excel без макросов он не воспроизводится и потому в таблицу не вынесен. | G37: =Ряд!H38-Ряд!H37 | H37: =Ряд!H39-Ряд!H37 | I37: =Ряд!H40-Ряд!H37
A38: 4. Дрейф | G38: =Ряд!H39-Ряд!H38 | H38: =Ряд!H40-Ряд!H38
A39: Средний прирост за месяц | B39: есть ли систематический снос ряда вверх | C39: AVERAGE(d) | D39: =AVERAGE(d) | E39: новое | G39: =Ряд!H40-Ряд!H39
A40: Дрейф за 3 месяца | B40: во что он превращается на горизонте буфера | C40: AVERAGE(d)*3 | D40: =AVERAGE(d)*3 | E40: новое
A41: 0,10 пп против буфера 9,03 — меньше 1 %. Допущение нулевого дрейфа безвредно, слагаемое μ·T в формулу не добавляется.
...

Sheet Зоны
A1: Светофор: зоны, определения, границы, действия
A2: Определения зон — дословно п. 18 Правил № 86 (Правила формирования системы управления рисками и внутреннего контроля, постановление Правления АРРФР от 28.04.2026 № 86, Минюст № 38586 от 29.04.2026). Своих формулировок здесь нет. Границы считаются из волатильности самой метрики, лимит приходит из Приложения № 3 к Политике — подобранных чисел на листе нет ни одного.
A4: Зона | B4: Определение по п. 18 Правил № 86 | C4: Нижняя граница | D4: Верхняя граница | E4: Формула границы | F4: Набл. | G4: Доля, %
A5: Зелёная | B5: уровень, не требующий применения корректирующих мер | C5: — | D5: ='Расчёт'!D29 | E5: — … L − M(4) | F5: =COUNTIF(v,"<"&'Расчёт'!D29) | G5: =F5/COUNT(v)*100
A6: Жёлтая | B6: уровень, определённый как допустимый, но требующий отдельных корректирующих мер в действующих процедурах системы управления рисками с целью снижения уровня риска | C6: ='Расчёт'!D29 | D6: ='Расчёт'!D17 | E6: L − M(4) … L − M(1) | F6: =COUNTIFS(v,">="&'Расчёт'!D29,v,"<"&'Расчёт'!D17) | G6: =F6/COUNT(v)*100
A7: Красная | B7: уровень, определённый как высокий, требующий применения соответствующих мер с целью недопущения ухудшения финансовой устойчивости банка и его платёжеспособности | C7: ='Расчёт'!D17 | D7: ='Расчёт'!D12 | E7: L − M(1) … L | F7: =COUNTIFS(v,">="&'Расчёт'!D17,v,"<"&'Расчёт'!D12) | G7: =F7/COUNT(v)*100
A8: Нарушение лимита | B8: действующий уровень риск-аппетита превышен. Отдельное состояние, а не зона: зоны описывают уровень риска, лимит — обязательство | C8: ='Расчёт'!D12 | D8: — | E8: L … — | F8: =COUNTIF(v,">="&'Расчёт'!D12) | G8: =F8/COUNT(v)*100
A9: Всего | F9: =SUM(F5:F8) | G9: =F9/COUNT(v)*100
A11: Где мы сейчас, 01.07.2026
A12: Текущее значение метрики | B12: ='Расчёт'!D8 | C12: доля топ-20 в собственном капитале, балансовая база
A13: Граница зелёная / жёлтая | B13: ='Расчёт'!D29 | C13: L − M(4)
A14: Граница жёлтая / красная | B14: ='Расчёт'!D17 | C14: L − M(1)
A15: Лимит | B15: ='Расчёт'!D12 | C15: 95 % в регуляторной базе ÷ k
A16: До красной, пп | B16: ='Расчёт'!D17-'Расчёт'!D8 | C16: меньше половины одного месячного σ
A17: До лимита, пп | B17: ='Расчёт'!D12-'Расчёт'!D8
A18: T* — месяцев до лимита | B18: ='Расчёт'!D45 | C18: ((L − v) / (z·σ))²
A19: Зона текущей точки | B19: =IF('Расчёт'!D8>='Расчёт'!D12,"НАРУШЕНИЕ ЛИМИТА",IF('Расчёт'!D8>='Расчёт'!D17,"КРАСНАЯ",IF('Расчёт'!D8>='Расчёт'!D29,"ЖЁЛТАЯ","ЗЕЛЁНАЯ"))) | C19: Жёлтая означает: уровень допустим, но требует отдельных корректирующих мер в действующих процедурах.
A21: Сколько стоит смена зоны, млн ₸
A22: Что сделать | B22: Через задолженность топ-20 | C22: Через собственный капитал | D22: Комментарий
A23: Вернуться в зелёную | B23: ='Расчёт'!D29/100*Ряд!D40-Ряд!B40 | C23: =Ряд!B40/('Расчёт'!D29/100)-Ряд!D40 | D23: самая дорогая из трёх: 3,3 пп ниже текущей точки
A24: Не войти в красную | B24: ='Расчёт'!D17/100*Ряд!D40-Ряд!B40 | C24: =Ряд!B40/('Расчёт'!D17/100)-Ряд!D40 | D24: запас, который есть сейчас; один средний месяц по σ больше него вдвое
A25: Не нарушить лимит | B25: ='Расчёт'!D12/100*Ряд!D40-Ряд!B40 | C25: =Ряд!B40/('Расчёт'!D12/100)-Ряд!D40 | D25: формальный запас до обязательства
A26: Масштаб, определяющий всё остальное: одно среднее месячное движение по σ_Δ равно 17 989 млн ₸ задолженности при текущем капитале. Это вдвое больше запаса до красной зоны. Меры, которые начинают выбирать в момент срабатывания, опаздывают по построению — отсюда требование п. 18 № 86 брать их из ДЕЙСТВУЮЩИХ процедур, а не сочинять.
A28: Вероятность достичь границы за T месяцев
A29: Граница | B29: 1 месяц | C29: 2 месяца | D29: 3 месяца | E29: 6 месяцев | F29: Разрыв, пп
A30: Войти в красную зону | B30: =(1-NORMSDIST(('Расчёт'!D17-'Расчёт'!D8)/('Расчёт'!D6*SQRT(1))))*100 | C30: =(1-NORMSDIST(('Расчёт'!D17-'Расчёт'!D8)/('Расчёт'!D6*SQRT(2))))*100 | D30: =(1-NORMSDIST(('Расчёт'!D17-'Расчёт'!D8)/('Расчёт'!D6*SQRT(3))))*100 | E30: =(1-NORMSDIST(('Расчёт'!D17-'Расчёт'!D8)/('Расчёт'!D6*SQRT(6))))*100 | F30: ='Расчёт'!D17-'Расчёт'!D8
A31: Нарушить лимит | B31: =(1-NORMSDIST(('Расчёт'!D12-'Расчёт'!D8)/('Расчёт'!D6*SQRT(1))))*100 | C31: =(1-NORMSDIST(('Расчёт'!D12-'Расчёт'!D8)/('Расчёт'!D6*SQRT(2))))*100 | D31: =(1-NORMSDIST(('Расчёт'!D12-'Расчёт'!D8)/('Расчёт'!D6*SQRT(3))))*100 | E31: =(1-NORMSDIST(('Расчёт'!D12-'Расчёт'!D8)/('Расчёт'!D6*SQRT(6))))*100 | F31: ='Расчёт'!D12-'Расчёт'!D8
A32: Считано по нормальной модели с нулевым дрейфом — тем же допущением, что и M(T), и проверенным на листе «Обоснование M(T)». Главное число: вероятность войти в красную зону в течение одного месяца — около 32 %. Это не прогноз, а мера близости: разрыв до красной меньше половины месячного σ.
A34: План действий по зонам — предложение, требующее решений
A35: Зона | B35: Наблюдение | C35: Уведомление | D35: Меры | E35: Что документируется | F35: Вопрос, который надо закрыть
A36: Зелёная | B36: Ежемесячно, штатный отчёт | C36: Штатный отчёт | D36: Не требуются | E36: — | F36: Ничего. Формулировка зоны прямо говорит «не требующий мер» — добавлять действия сюда значит противоречить определению
A37: Жёлтая | B37: Еженедельно, с гистерезисом | C37: БРМ → КРВК, срок не установлен | D37: Из действующих процедур: получение денежного обеспечения (вычитается из числителя метрики напрямую); остановка прироста задолженности топ-20 и пролонгаций | E37: Решение о применении меры либо мотивированный отказ | F37: 1) Какие именно действующие процедуры содержат эти меры — норма требует брать существующие, а не вводить новые. 2) N месяцев подряд ниже границы для выхода из зоны (гистерезис). 3) Срок уведомления КРВК
A38: Красная | B38: Еженедельно + внеочередной расчёт | C38: СД через КРВК, незамедлительно | D38: Те же меры плюс план снижения с датой возврата в жёлтую. Синдикация и уступка части требуют контрагента и в один месяц не укладываются | E38: Письменный план устранения с ответственным и датой | F38: 1) Уведомляется ли АРРФР и на каком основании — смотреть Правила № 272 о мерах надзорного реагирования. 2) Согласование с триггерами режима восстановления по № 119: красная зона использует их словарь («финансовая устойчивость и платёжеспособность»), и две системы не должны противоречить
A39: Нарушение лимита | B39: Еженедельно + внеочередной расчёт | C39: СД, протокол УО | D39: Устранение нарушения по Политике п. 12-1 и п. 27 | E39: Письменное описание того, как нарушение будет или было устранено | F39: Конкретных мер и сроков в Политике НЕТ — это записанный пробел ВНД, а не пропуск в книге. Закрывается правкой Политики, не расчётом
A41: Структура режима взята из OCC Heightened Standards II.H (см. BENCHMARK.md): выявление; РАЗЛИЧЕНИЕ нарушений по тяжести последствий; протокол уведомления первой линии, БРМ, внутреннего аудита, СД и регулятора; письменное описание устранения; ответственность с учётом величины, частоты и повторяемости. Из пяти элементов в нашей Политике есть один — факт нарушения. Остальные четыре и есть содержание правки.
A42: ЧТО НА ЭТОМ ЛИСТЕ НЕ ДОКАЗАНО. Первое: п. 18 Правил № 86 и Приложение № 2 к Методике дословно не разобраны; определения зон взяты из конспекта SPRAVOCHNIK_RA.md, а не из оригинала. Второе, важнее: при лестничной разметке действующий уровень 95 %% выполняет роль риск-ёмкости, а уровнем риск-аппетита становится граница зелёной зоны — это смена смысла числа 95, и её принимает уполномоченный орган, а не расчёт. Находка Р1 показывает, что на восьми метриках Банк уже так и делает.
A43: Ряд и лестница зон. Собрано viz/zone_ladder.py из того же CSV, что и расчёт, — границы на картинке и в таблице совпадают по построению.
A79: Находка Р1: у восьми метрик, где зоны уже установлены, порог красной стоит ЗА уровнем риск-аппетита. Это довод за лестницу, и он не наш — так уже сделано в Банке.

Sheet Две сигмы
A1: Две σ в одной таблице методов — и они про разное
A2: Остаток находки Р-Д1. Третья σ принадлежала методу B, который из книги убран: он не защищается на комитете. В DISCLOSURE.md Р-Д1 остаётся целиком — там он про чужую опубликованную таблицу, а не про нашу книгу.
A4: Методы | B4: Какая σ | C4: Значение | D4: К σ_Δ | E4: Что из этого следует
A5: D, H | B5: выборочное с.к.о. приростов, все 35 | C5: ='Расчёт'!D6 | D5: =C5/'Расчёт'!D6 | E5: Базовая. На ней стоят запас M(T), расстояние D и T*
A6: М1 | B6: выборочное с.к.о. самих уровней, не приростов | C6: ='Расчёт'!D7 | D6: =C6/'Расчёт'!D6 | E6: Мера разброса уровня за три года, а не месячного хода. С первой несопоставима в принципе: одна про то, где ряд стоял, другая про то, как быстро он движется
A8: Правило, которое из этого остаётся: σ называется прямо в строке метода. Метод, защищаемый в собственных терминах, несравним с методом, защищаемым в своих, — и разница в 53 % между этими двумя σ тому иллюстрация.

Sheet Триггеры
A1: Триггеры на движение: ΔСК ≤ −3 % или ΔЗайм ≥ +5 % за месяц
A2: Срабатывают независимо от зоны. Все 35 приростов показаны целиком — выборка из шести строк недоказуема: по ней не видно, что остальные 29 условию не отвечают.
A4: Дата | B4: ΔСК, % | C4: ΔЗайм, % | D4: Коэффициент | E4: Что сработало
A5: ='Ряд'!A6 | B5: ='Ряд'!K6 | C5: ='Ряд'!L6 | D5: ='Ряд'!H6 | E5: ='Ряд'!M6
A6: ='Ряд'!A7 | B6: ='Ряд'!K7 | C6: ='Ряд'!L7 | D6: ='Ряд'!H7 | E6: ='Ряд'!M7
A7: ='Ряд'!A8 | B7: ='Ряд'!K8 | C7: ='Ряд'!L8 | D7: ='Ряд'!H8 | E7: ='Ряд'!M8
A8: ='Ряд'!A9 | B8: ='Ряд'!K9 | C8: ='Ряд'!L9 | D8: ='Ряд'!H9 | E8: ='Ряд'!M9
A9: ='Ряд'!A10 | B9: ='Ряд'!K10 | C9: ='Ряд'!L10 | D9: ='Ряд'!H10 | E9: ='Ряд'!M10
A10: ='Ряд'!A11 | B10: ='Ряд'!K11 | C10: ='Ряд'!L11 | D10: ='Ряд'!H11 | E10: ='Ряд'!M11
A11: ='Ряд'!A12 | B11: ='Ряд'!K12 | C11: ='Ряд'!L12 | D11: ='Ряд'!H12 | E11: ='Ряд'!M12
A12: ='Ряд'!A13 | B12: ='Ряд'!K13 | C12: ='Ряд'!L13 | D12: ='Ряд'!H13 | E12: ='Ряд'!M13
A13: ='Ряд'!A14 | B13: ='Ряд'!K14 | C13: ='Ряд'!L14 | D13: ='Ряд'!H14 | E13: ='Ряд'!M14
A14: ='Ряд'!A15 | B14: ='Ряд'!K15 | C14: ='Ряд'!L15 | D14: ='Ряд'!H15 | E14: ='Ряд'!M15
A15: ='Ряд'!A16 | B15: ='Ряд'!K16 | C15: ='Ряд'!L16 | D15: ='Ряд'!H16 | E15: ='Ряд'!M16
A16: ='Ряд'!A17 | B16: ='Ряд'!K17 | C16: ='Ряд'!L17 | D16: ='Ряд'!H17 | E16: ='Ряд'!M17
... A39: ='Ряд'!A40 | B39: ='Ряд'!K40 | C39: ='Ряд'!L40 | D39: ='Ряд'!H40 | E39: ='Ряд'!M40
A41: Сработало | B41: =COUNTIF(E5:E39,"Займ")+COUNTIF(E5:E39,"СК")+COUNTIF(E5:E39,"оба") | C41: =B41/35*100 | D41: из 35 приростов, %
A43: Строка 01.2026 — та, ради которой триггеры и заводятся: вход сделан капиталом (ΔСК = −7,92 %), а не портфелем, и уровневая зона его не предупреждала в принципе. Зона смотрит на значение коэффициента, триггер — на его движение. Формула M(T) описывает диффузию, триггер ловит скачок; ни один из двух инструментов не заменяет другой.

Sheet Метрики — ряд
A1: Месячный ряд розничных метрик: 36 точек, 01.08.2023 — 01.07.2026
A2: Источник: лист Monthly книги Приложения № 3 к Политике, получен 04.09.2026. Значения в процентах — в исходном листе они долями. Сверено с квартальной формой № 50 на 01.07.2026: максимальное расхождение 0,0009 пп. ОГОВОРКА (DECOMPOSITION § 10.2): из 36 месяцев с отчётностью сверены 20, первые 16 — реконструкция, величин уполномоченный орган не видел.
A4: Метрика | B4: Сегмент | C4: Лимит L | D4: 2023-08 | E4: 2023-09 | F4: 2023-10 | G4: 2023-11 | H4: 2023-12 | I4: 2024-01 | J4: 2024-02 | K4: 2024-03 | L4: 2024-04 | M4: 2024-05 | N4: 2024-06 | O4: 2024-07 | P4: 2024-08 | Q4: 2024-09 | R4: 2024-10 | S4: 2024-11 | T4: 2024-12 | U4: 2025-01 | V4: 2025-02 | W4: 2025-03 | X4: 2025-04 | Y4: 2025-05 | Z4: 2025-06 | AA4: 2025-07 | AB4: 2025-08 | AC4: 2025-09 | AD4: 2025-10 | AE4: 2025-11 | AF4: 2025-12 | AG4: 2026-01 | AH4: 2026-02 | AI4: 2026-03 | AJ4: 2026-04 | AK4: 2026-05 | AL4: 2026-06 | AM4: 2026-07 | AO4: Δ1 | AP4: Δ2 | AQ4: Δ3 | AR4: Δ4 | AS4: Δ5 | AT4: Δ6 | AU4: Δ7 | AV4: Δ8 | AW4: Δ9 | AX4: Δ10 | AY4: Δ11 | AZ4: Δ12 | BA4: Δ13 | BB4: Δ14 | BC4: Δ15 | BD4: Δ16 | BE4: Δ17 | BF4: Δ18 | BG4: Δ19 | BH4: Δ20 | BI4: Δ21 | BJ4: Δ22 | BK4: Δ23 | BL4: Δ24 | BM4: Δ25 | BN4: Δ26 | BO4: Δ27 | BP4: Δ28 | BQ4: Δ29 | BR4: Δ30 | BS4: Δ31 | BT4: Δ32 | BU4: Δ33 | BV4: Δ34 | BW4: Δ35
A5: EL — ожидаемые потери, всего | B5: RB | C5: 9 | D5: 4.01893 | E5: 4.006073 | F5: 3.918858 | G5: 3.916775 | H5: 3.902911 | I5: 3.860625 | J5: 3.783252 | K5: 3.753594 | L5: 3.705587 | M5: 3.746765 | N5: 3.861943 | O5: 3.763018 | P5: 3.619708 | Q5: 3.587173 | R5: 3.411962 | S5: 3.067174 | T5: 3.066544 | U5: 3.032757 | V5: 2.944715 | W5: 2.92572 | X5: 2.918222 | Y5: 2.896367 | Z5: 2.896783 | AA5: 2.784058 | AB5: 2.763943 | AC5: 2.682605 | AD5: 2.634274 | AE5: 2.58102 | AF5: 2.536831 | AG5: 2.615049 | AH5: 2.616212 | AI5: 2.671571 | AJ5: 2.713037 | AK5: 2.711398 | AL5: 2.718967 | AM5: 2.757284 | AO5: =E5-D5 | AP5: =F5-E5 | AQ5: =G5-F5 | AR5: =H5-G5 | AS5: =I5-H5 | AT5: =J5-I5 | AU5: =K5-J5 | AV5: =L5-K5 | ... BW5: =AM5-AL5
A6: EL — необеспеченные | B6: RB | C6: 10 | D6: 7.423354 | E6: 7.500904 | F6: 7.404206 | G6: 7.442255 | H6: 7.630703 | I6: 7.607814 | J6: 7.565199 | K6: 7.556539 | L6: 7.545619 | M6: 7.541218 | N6: 7.699862 | O6: 7.656452 | P6: 7.489877 | Q6: 7.385384 | R6: 7.223349 | S6: 6.880542 | T6: 7.034851 | U6: 7.219599 | V6: 7.049311 | W6: 7.13935 | X6: 7.081359 | Y6: 7.078887 | Z6: 7.126308 | AA6: 7.074532 | AB6: 7.164825 | AC6: 7.147442 | AD6: 7.099976 | AE6: 7.092606 | AF6: 7.069679 | AG6: 7.031319 | AH6: 7.029701 | AI6: 7.028161 | AJ6: 7.011424 | AK6: 7.3706 | AL6: 7.377971 | AM6: 7.566672 | AO6: =E6-D6 | AP6: =F6-E6 | AQ6: =G6-F6 | AR6: =H6-G6 | AS6: =I6-H6 | AT6: =J6-I6 | AU6: =K6-J6 | AV6: =L6-K6 | ... BW6: =AM6-AL6
A7: EL — обеспеченные | B7: RB | C7: 7 | D7: 1.334152 | E7: 1.334097 | F7: 1.324876 | G7: 1.363572 | H7: 1.347993 | I7: 1.424419 | J7: 1.395834 | K7: 1.412628 | L7: 1.416922 | M7: 1.481267 | N7: 1.570876 | O7: 1.497854 | P7: 1.435108 | Q7: 1.443728 | R7: 1.338809 | S7: 1.235632 | T7: 1.311974 | U7: 1.327887 | V7: 1.315344 | W7: 1.32047 | X7: 1.365542 | Y7: 1.381124 | Z7: 1.397907 | AA7: 1.370362 | AB7: 1.3795 | AC7: 1.349421 | AD7: 1.348437 | AE7: 1.322858 | AF7: 1.308495 | AG7: 1.427522 | AH7: 1.449854 | AI7: 1.528519 | AJ7: 1.589895 | AK7: 1.552727 | AL7: 1.606792 | AM7: 1.635852 | AO7: =E7-D7 | AP7: =F7-E7 | AQ7: =G7-F7 | AR7: =H7-G7 | AS7: =I7-H7 | AT7: =J7-I7 | AU7: =K7-J7 | AV7: =L7-K7 | ... BW7: =AM7-AL7
A8: EL — прочие | B8: RB | C8: 10 | D8: 3.326879 | E8: 3.202222 | F8: 3.1625 | G8: 3.149127 | H8: 3.160358 | I8: 3.051504 | J8: 3.056607 | K8: 3.012888 | L8: 3.014183 | M8: 2.959452 | N8: 3.013192 | O8: 3.064589 | P8: 2.827206 | Q8: 2.773865 | R8: 2.754806 | S8: 2.752117 | T8: 2.65327 | U8: 2.565213 | V8: 2.612028 | W8: 2.654717 | X8: 2.738199 | Y8: 2.571633 | Z8: 2.445707 | AA8: 2.403899 | AB8: 2.404753 | AC8: 2.376893 | AD8: 2.546951 | AE8: 2.561576 | AF8: 2.542604 | AG8: 2.455625 | AH8: 2.303325 | AI8: 2.321167 | AJ8: 2.289344 | AK8: 2.348211 | AL8: 2.306177 | AM8: 2.471786 | AO8: =E8-D8 | AP8: =F8-E8 | AQ8: =G8-F8 | AR8: =H8-G8 | AS8: =I8-H8 | AT8: =J8-I8 | AU8: =K8-J8 | AV8: =L8-K8 | ... BW8: =AM8-AL8
A9: PD — необеспеченные | B9: RB | C9: 15 | D9: 11.60745 | E9: 11.60097 | F9: 11.557592 | G9: 11.600434 | H9: 11.609779 | I9: 11.578222 | J9: 11.504748 | K9: 11.470526 | L9: 11.567866 | M9: 11.537957 | N9: 11.689138 | O9: 11.74201 | P9: 11.687766 | Q9: 11.716373 | R9: 11.627811 | S9: 11.221708 | T9: 11.558577 | U9: 11.760264 | V9: 11.559204 | W9: 11.592315 | X9: 11.533197 | Y9: 11.505819 | Z9: 11.613521 | AA9: 11.503023 | AB9: 11.624704 | AC9: 11.571404 | AD9: 11.538188 | AE9: 11.503777 | AF9: 11.398796 | AG9: 11.227537 | AH9: 11.207139 | AI9: 11.177429 | AJ9: 11.041782 | AK9: 11.006035 | AL9: 10.98054 | AM9: 10.961171 | AO9: =E9-D9 | AP9: =F9-E9 | AQ9: =G9-F9 | AR9: =H9-G9 | AS9: =I9-H9 | AT9: =J9-I9 | AU9: =K9-J9 | AV9: =L9-K9 | ... BW9: =AM9-AL9
A10: PD — необеспеченные, наличные | B10: RB | C10: 15 | D10: 11.674808 | E10: 11.668178 | F10: 11.61045 | G10: 11.661356 | H10: 11.655618 | I10: 11.614657 | J10: 11.584871 | K10: 11.584976 | L10: 11.69753 | M10: 11.659563 | N10: 11.865741 | O10: 11.917347 | P10: 11.843573 | Q10: 11.888088 | R10: 11.812672 | S10: 11.320271 | T10: 11.711669 | U10: 11.95958 | V10: 11.735592 | W10: 11.762706 | X10: 11.704674 | Y10: 11.675266 | Z10: 11.795348 | AA10: 11.668777 | AB10: 11.789555 | AC10: 11.726212 | AD10: 11.70914 | AE10: 11.651701 | AF10: 11.531915 | AG10: 11.341787 | AH10: 11.319256 | AI10: 11.279728 | AJ10: 11.12813 | AK10: 11.092788 | AL10: 11.065915 | AM10: 11.046123 | AO10: =E10-D10 | AP10: =F10-E10 | AQ10: =G10-F10 | AR10: =H10-G10 | AS10: =I10-H10 | AT10: =J10-I10 | AU10: =K10-J10 | AV10: =L10-K10 | ... BW10: =AM10-AL10
A11: PD — необеспеченные, товарные | B11: RB | C11: 15 | D11: 11.50521 | E11: 11.50766 | F11: 11.54243 | G11: 11.55294 | H11: 11.651115 | I11: 11.668182 | J11: 11.352983 | K11: 11.106068 | L11: 11.114965 | M11: 11.141404 | N11: 10.962641 | O11: 11.007145 | P11: 11.075746 | Q11: 11.00069 | R11: 10.821536 | S11: 10.931785 | T11: 10.944521 | U11: 10.843042 | V11: 10.762585 | W11: 10.804766 | X11: 10.735113 | Y11: 10.688897 | Z11: 10.682042 | AA11: 10.659418 | AB11: 10.766198 | AC11: 10.756449 | AD11: 10.534971 | AE11: 10.655369 | AF11: 10.633609 | AG11: 10.600999 | AH11: 10.577046 | AI11: 10.597294 | AJ11: 10.629639 | AK11: 10.577601 | AL11: 10.612922 | AM11: 10.586523 | AO11: =E11-D11 | AP11: =F11-E11 | AQ11: =G11-F11 | AR11: =H11-G11 | AS11: =I11-H11 | AT11: =J11-I11 | AU11: =K11-J11 | AV11: =L11-K11 | ... BW11: =AM11-AL11
A12: PD — обеспеченные | B12: RB | C12: 7 | D12: 4.686167 | E12: 4.757833 | F12: 4.71486 | G12: 4.769401 | H12: 4.703394 | I12: 4.713498 | J12: 4.709291 | K12: 4.765951 | L12: 4.872496 | M12: 4.872588 | N12: 5.174162 | O12: 5.1579 | P12: 5.192143 | Q12: 5.284508 | R12: 5.078941 | S12: 4.80978 | T12: 5.05383 | U12: 5.056691 | V12: 5.062908 | W12: 5.10031 | X12: 5.158827 | Y12: 5.188293 | Z12: 5.265188 | AA12: 5.145208 | AB12: 5.170206 | AC12: 5.180577 | AD12: 5.147123 | AE12: 5.141497 | AF12: 5.07536 | AG12: 5.087058 | AH12: 5.094358 | AI12: 5.105313 | AJ12: 5.097632 | AK12: 5.027749 | AL12: 5.033045 | AM12: 5.014115 | AO12: =E12-D12 | AP12: =F12-E12 | AQ12: =G12-F12 | AR12: =H12-G12 | AS12: =I12-H12 | AT12: =J12-I12 | AU12: =K12-J12 | AV12: =L12-K12 | ... BW12: =AM12-AL12
A13: PD — прочие | B13: RB | C13: 14 | D13: 5.170665 | E13: 4.970544 | F13: 4.914703 | G13: 4.891764 | H13: 4.888883 | I13: 4.727811 | J13: 4.681111 | K13: 4.61092 | L13: 4.614513 | M13: 4.586092 | N13: 4.54441 | O13: 4.62125 | P13: 4.498773 | Q13: 4.443795 | R13: 4.469202 | S13: 4.463136 | T13: 4.299537 | U13: 4.234974 | V13: 4.355903 | W13: 4.396757 | X13: 4.471538 | Y13: 4.195269 | Z13: 4.12505 | AA13: 4.047016 | AB13: 4.042882 | AC13: 3.989124 | AD13: 4.268485 | AE13: 4.285341 | AF13: 4.248105 | AG13: 4.089569 | AH13: 3.828689 | AI13: 3.845012 | AJ13: 3.778529 | AK13: 3.723774 | AL13: 3.646836 | AM13: 3.654987 | AO13: =E13-D13 | AP13: =F13-E13 | AQ13: =G13-F13 | AR13: =H13-G13 | AS13: =I13-H13 | AT13: =J13-I13 | AU13: =K13-J13 | AV13: =L13-K13 | ... BW13: =AM13-AL13

Sheet Метрики
A1: Зоны по всем кредитным метрикам, месячные ряды по 36 точек
A2: Границы те же, что на листе «Зоны»: зелёная до L − M(4), жёлтая до L − M(1), красная до лимита. Колонки «% лимита» — та же граница как X = 1 − M(T)/L. Ряд топ-20 и CoR — на листе «Ряд», розничных метрик — на «Метрики — ряд».
A4: Метрика | B4: Сегмент | C4: Лимит L | D4: Точек | E4: Шаг, мес | F4: σ_Δ | G4: M(4 мес) | H4: M(1 мес) | I4: Зел./жёлт. | J4: Жёлт./красн. | K4: Зел./жёлт., % L | L4: Жёлт./красн., % L | M4: Факт | N4: Зона | O4: D, σ | P4: SE(σ)
A5: Топ-20 / собственный капитал | B5: KB | C5: ='Расчёт'!D12 | D5: ='Расчёт'!D10 | E5: =1 | F5: ='Расчёт'!D6 | G5: ='Расчёт'!D28 | H5: ='Расчёт'!D16 | I5: ='Расчёт'!D29 | J5: ='Расчёт'!D17 | K5: =I5/C5*100 | L5: =J5/C5*100 | M5: ='Расчёт'!D8 | N5: =IF(M5>=C5,"НАРУШЕНИЕ",IF(M5>=J5,"КРАСНАЯ",IF(M5>=I5,"ЖЁЛТАЯ","зелёная"))) | O5: =(C5-M5)/F5 | P5: =F5/SQRT(2*(D5-2))
A6: CoR — стоимость риска (KB_PB) | B6: KB_PB | C6: 3 | D6: =COUNT(cor_kb) | E6: 1 | F6: =STDEV(d_cor_kb) | G6: =z_p*F6*SQRT(4/E6) | H6: =z_p*F6*SQRT(1/E6) | I6: =C6-G6 | J6: =C6-H6 | K6: =I6/C6*100 | L6: =J6/C6*100 | M6: ='Ряд'!O40 | N6: =IF(M6>=C6,"НАРУШЕНИЕ",IF(M6>=J6,"КРАСНАЯ",IF(M6>=I6,"ЖЁЛТАЯ","зелёная"))) | O6: =(C6-M6)/F6 | P6: =F6/SQRT(2*(D6-2))
A7: CoR — стоимость риска (MSB) | B7: MSB | C7: 3.5 | D7: =COUNT(cor_ms) | E7: 1 | F7: =STDEV(d_cor_ms) | G7: =z_p*F7*SQRT(4/E7) | H7: =z_p*F7*SQRT(1/E7) | I7: =C7-G7 | J7: =C7-H7 | K7: =I7/C7*100 | L7: =J7/C7*100 | M7: ='Ряд'!R40 | N7: =IF(M7>=C7,"НАРУШЕНИЕ",IF(M7>=J7,"КРАСНАЯ",IF(M7>=I7,"ЖЁЛТАЯ","зелёная"))) | O7: =(C7-M7)/F7 | P7: =F7/SQRT(2*(D7-2))
A8: ='Метрики — ряд'!A5 | B8: ='Метрики — ряд'!B5 | C8: ='Метрики — ряд'!C5 | D8: =COUNT('Метрики — ряд'!D5:AM5) | E8: 1 | F8: =STDEV('Метрики — ряд'!AO5:BW5) | G8: =z_p*F8*SQRT(4/E8) | H8: =z_p*F8*SQRT(1/E8) | I8: =C8-G8 | J8: =C8-H8 | K8: =I8/C8*100 | L8: =J8/C8*100 | M8: ='Метрики — ряд'!AM5 | N8: =IF(M8>=C8,"НАРУШЕНИЕ",IF(M8>=J8,"КРАСНАЯ",IF(M8>=I8,"ЖЁЛТАЯ","зелёная"))) | O8: =(C8-M8)/F8 | P8: =F8/SQRT(2*(D8-2))
A9: ='Метрики — ряд'!A6 | B9: ='Метрики — ряд'!B6 | C9: ='Метрики — ряд'!C6 | D9: =COUNT('Метрики — ряд'!D6:AM6) | E9: 1 | F9: =STDEV('Метрики — ряд'!AO6:BW6) | G9: =z_p*F9*SQRT(4/E9) | H9: =z_p*F9*SQRT(1/E9) | I9: =C9-G9 | J9: =C9-H9 | K9: =I9/C9*100 | L9: =J9/C9*100 | M9: ='Метрики — ряд'!AM6 | N9: =IF(M9>=C9,"НАРУШЕНИЕ",IF(M9>=J9,"КРАСНАЯ",IF(M9>=I9,"ЖЁЛТАЯ","зелёная"))) | O9: =(C9-M9)/F9 | P9: =F9/SQRT(2*(D9-2))
A10: ='Метрики — ряд'!A7 | B10: ='Метрики — ряд'!B7 | C10: ='Метрики — ряд'!C7 | D10: =COUNT('Метрики — ряд'!D7:AM7) | E10: 1 | F10: =STDEV('Метрики — ряд'!AO7:BW7) | G10: =z_p*F10*SQRT(4/E10) | H10: =z_p*F10*SQRT(1/E10) | I10: =C10-G10 | J10: =C10-H10 | K10: =I10/C10*100 | L10: =J10/C10*100 | M10: ='Метрики — ряд'!AM7 | N10: =IF(M10>=C10,"НАРУШЕНИЕ",IF(M10>=J10,"КРАСНАЯ",IF(M10>=I10,"ЖЁЛТАЯ","зелёная"))) | O10: =(C10-M10)/F10 | P10: =F10/SQRT(2*(D10-2))
A11: ='Метрики — ряд'!A8 | B11: ='Метрики — ряд'!B8 | C11: ='Метрики — ряд'!C8 | D11: =COUNT('Метрики — ряд'!D8:AM8) | E11: 1 | F11: =STDEV('Метрики — ряд'!AO8:BW8) | G11: =z_p*F11*SQRT(4/E11) | H11: =z_p*F11*SQRT(1/E11) | I11: =C11-G11 | J11: =C11-H11 | K11: =I11/C11*100 | L11: =J11/C11*100 | M11: ='Метрики — ряд'!AM8 | N11: =IF(M11>=C11,"НАРУШЕНИЕ",IF(M11>=J11,"КРАСНАЯ",IF(M11>=I11,"ЖЁЛТАЯ","зелёная"))) | O11: =(C11-M11)/F11 | P11: =F11/SQRT(2*(D11-2))
A12: ='Метрики — ряд'!A9 | B12: ='Метрики — ряд'!B9 | C12: ='Метрики — ряд'!C9 | D12: =COUNT('Метрики — ряд'!D9:AM9) | E12: 1 | F12: =STDEV('Метрики — ряд'!AO9:BW9) | G12: =z_p*F12*SQRT(4/E12) | H12: =z_p*F12*SQRT(1/E12) | I12: =C12-G12 | J12: =C12-H12 | K12: =I12/C12*100 | L12: =J12/C12*100 | M12: ='Метрики — ряд'!AM9 | N12: =IF(M12>=C12,"НАРУШЕНИЕ",IF(M12>=J12,"КРАСНАЯ",IF(M12>=I12,"ЖЁЛТАЯ","зелёная"))) | O12: =(C12-M12)/F12 | P12: =F12/SQRT(2*(D12-2))
A13: ='Метрики — ряд'!A10 | B13: ='Метрики — ряд'!B10 | C13: ='Метрики — ряд'!C10 | D13: =COUNT('Метрики — ряд'!D10:AM10) | E13: 1 | F13: =STDEV('Метрики — ряд'!AO10:BW10) | G13: =z_p*F13*SQRT(4/E13) | H13: =z_p*F13*SQRT(1/E13) | I13: =C13-G13 | J13: =C13-H13 | K13: =I13/C13*100 | L13: =J13/C13*100 | M13: ='Метрики — ряд'!AM10 | N13: =IF(M13>=C13,"НАРУШЕНИЕ",IF(M13>=J13,"КРАСНАЯ",IF(M13>=I13,"ЖЁЛТАЯ","зелёная"))) | O13: =(C13-M13)/F13 | P13: =F13/SQRT(2*(D13-2))
A14: ='Метрики — ряд'!A11 | B14: ='Метрики — ряд'!B11 | C14: ='Метрики — ряд'!C11 | D14: =COUNT('Метрики — ряд'!D11:AM11) | E14: 1 | F14: =STDEV('Метрики — ряд'!AO11:BW11) | G14: =z_p*F14*SQRT(4/E14) | H14: =z_p*F14*SQRT(1/E14) | I14: =C14-G14 | J14: =C14-H14 | K14: =I14/C14*100 | L14: =J14/C14*100 | M14: ='Метрики — ряд'!AM11 | N14: =IF(M14>=C14,"НАРУШЕНИЕ",IF(M14>=J14,"КРАСНАЯ",IF(M14>=I14,"ЖЁЛТАЯ","зелёная"))) | O14: =(C14-M14)/F14 | P14: =F14/SQRT(2*(D14-2))
A15: ='Метрики — ряд'!A12 | B15: ='Метрики — ряд'!B12 | C15: ='Метрики — ряд'!C12 | D15: =COUNT('Метрики — ряд'!D12:AM12) | E15: 1 | F15: =STDEV('Метрики — ряд'!AO12:BW12) | G15: =z_p*F15*SQRT(4/E15) | H15: =z_p*F15*SQRT(1/E15) | I15: =C15-G15 | J15: =C15-H15 | K15: =I15/C15*100 | L15: =J15/C15*100 | M15: ='Метрики — ряд'!AM12 | N15: =IF(M15>=C15,"НАРУШЕНИЕ",IF(M15>=J15,"КРАСНАЯ",IF(M15>=I15,"ЖЁЛТАЯ","зелёная"))) | O15: =(C15-M15)/F15 | P15: =F15/SQRT(2*(D15-2))
A16: ='Метрики — ряд'!A13 | B16: ='Метрики — ряд'!B13 | C16: ='Метрики — ряд'!C13 | D16: =COUNT('Метрики — ряд'!D13:AM13) | E16: 1 | F16: =STDEV('Метрики — ряд'!AO13:BW13) | G16: =z_p*F16*SQRT(4/E16) | H16: =z_p*F16*SQRT(1/E16) | I16: =C16-G16 | J16: =C16-H16 | K16: =I16/C16*100 | L16: =J16/C16*100 | M16: ='Метрики — ряд'!AM13 | N16: =IF(M16>=C16,"НАРУШЕНИЕ",IF(M16>=J16,"КРАСНАЯ",IF(M16>=I16,"ЖЁЛТАЯ","зелёная"))) | O16: =(C16-M16)/F16 | P16: =F16/SQRT(2*(D16-2))
A18: Все двенадцать метрик — на месячных рядах по 36 точек | B18: Так стало с 15.09.2026. Первые две редакции листа считали девять розничных метрик и CoR на квартальном ряде из девяти точек, хотя месячные существовали: CoR — в том же файле, что и топ-20, EL и PD — на листе Monthly. Цена ошибки видна на CoR КБ/ПБ: σ 0,8514 вместо 1,2817, и метрика была показана зелёной, хотя она жёлтая.
A19: У CoR КБ/ПБ буфер больше самого лимита — и причина не в зонах (Г36) | B19: M(4) = 3,2850 при лимите 3,00, поэтому граница зелёной уходит в минус (−0,2850), и колонка K показывает −9,5 %. Ранее это было записано здесь как свойство метрики — формулировка неверна и отозвана. Причина в ряде: σ по CoR не однородна по календарю. σ(февраль–март) = 3,0257 против σ(остальные) = 0,5998, отношение 5,04; пять приращений из 35 дают 87,4 % суммы квадратов, и все пять — январь–март. У десяти остальных метрик такого режима нет (отношение ≤ 1,76, у топ-20 — 0,66). На обычных месяцах граница зелёной равна +1,4625, X = +48,8 %, и метрика ЗЕЛЁНАЯ, а не жёлтая; зато в окне закрытия M(1) = 3,8776 превышает лимит, и зона там не предупреждает ни о чём. Смешанная σ прячет обе половины. Лист сознательно оставлен на смешанной σ: причина февральского скачка неизвестна (три версии в Г36), и калибровать до ответа на запрос нельзя. Светофор здесь переключается: 25 / 9 / 2 / 0.
