Workbook
Name v: 'Ряд'!$H$5:$H$40
Name d: 'Ряд'!$J$6:$J$40
Name p_conf: 'Параметры'!$C$5
Name z_p: 'Параметры'!$C$6
Name k_G26: 'Параметры'!$C$7
Name L_reg: 'Параметры'!$C$8
Name T_cikl: 'Параметры'!$C$9
Name por_sk: 'Параметры'!$C$10
Name por_zaim: 'Параметры'!$C$11

Sheet Как защищать
A1: Расчётный лист по топ-20: как им пользоваться на комитете
A2: Редакция 14.09.2026. Собрано из data/top20_monthly_2023_08_2026_07.csv сборщиком build/raschet_list.py — правки вносятся в скрипт, а не в готовый файл. Сверка: python3 raschet_list.py --verify.
A4: Что в книге | B4: «Ряд» — 36 точек и всё, что считается построчно, обе базы капитала рядом. «Параметры» — семь входов, из них вычисляются два. «Расчёт» — каждое опубликованное число живой формулой против напечатанного. «Обоснование M(T)» — четыре проверки допущений формулы буфера. «Зоны» — разметка и где мы сейчас. «Две сигмы» — остаток Р-Д1. «Триггеры» — все 35 приростов.
A5: Главное свойство | B5: В книге нет ни одного вбитого руками результата, кроме одного помеченного (бутстрап). Любое число со слайда выделяется в колонке «Значение», и в строке формул видно, из чего оно получено. Несогласный с параметром меняет его на листе «Параметры», и вся книга пересчитывается при нём.
A6: «Откуда 108,63» | B6: Уровень 95 % задан в регуляторной базе капитала. С 01.01.2026 знаменатель метрики — балансовый капитал (Г26), k = 0,8745 есть отношение баз. 108,63 — тот же уровень в новой базе. Второй, независимый путь: квантиль 90 % ряда плюс запас на три месяца даёт 108,58. Сходимость двух путей на 0,05 пп и есть довод, что уровень не подогнан.
A7: «Почему корень из T» | B7: Складываются дисперсии, а не с.к.о.: сумма T независимых приростов имеет дисперсию T·σ², то есть разброс σ·√T. Держится это ровно на независимости. Лист «Обоснование M(T)», блок 1: автокорреляция −0,08 при пороге 0,34; фактический разброс трёхмесячных изменений 6,40 против модельных 7,04 — модель ЗАВЫШАЕТ, то есть ошибается в безопасную сторону.
A8: «Почему нормальное распределение» | B8: Нужна нормальность не приростов, а их трёхмесячной СУММЫ, к которой буфер и применяется. У приростов асимметрия 0,67, у суммы — 0,04. Жарк–Бера на приростах 2,70 при критических 5,99. И z(0,90) = 1,28 лежит в теле распределения, а не в хвосте: ошибки нормальности бьют на 99 %, не на 90 %. Лист «Обоснование M(T)», блок 2.
A9: «А буфер не выдуман» | B9: Три непараметрических способа дают 9,29, 9,35 и 9,37 против модельных 9,03 — разброс 3,6 % при собственной погрешности σ в ±1,09. И проверка на факте: движение апрель→июль 2026 составило +8,24 пп, то есть 91 % буфера. Буфер не подушка на всякий случай — ряд только что прошёл почти ровно такое движение.
A10: «Почему T = 3» | B10: Честный ответ: длина цикла решения не измерена и в регламенте не закреплена. Это записано как незакрытый пункт, а не спрятано. Поставьте на «Параметрах» T = 2 или T = 4 — уровень двигается примерно на 1,4–1,5 пп за месяц цикла.
A11: «Почему 90 %, а не 95 или 99» | B11: Это цена ложного отбоя, а не расчёт. При 90 % один ложный сигнал из десяти. Выше — жёлтая опускается и лампа горит почти всегда. Параметр p на листе «Параметры» меняется, z пересчитывается сам. Решение комитета, не наше.
A12: «Где мы сейчас» | B12: Лист «Зоны». Текущая точка 101,50 — жёлтая зона. До лимита 7,13 пп = 1,75 σ. T* = 1,87 месяца: столько остаётся до лимита при доверии 90 %. Красная зона за 36 месяцев загоралась один раз, пробоев не было ни разу.
A13: «А если ничего не менять» | B13: Лист «Расчёт», блок 7. При сохранении уровня 95 % жёлтая линия ложится на 85,97, и выше неё оказывается 31 наблюдение из 36. Светофор с постоянно горящей лампой не является системой раннего предупреждения.
A14: Четыре слабых места — назвать самому | B14: 1) Ряд обрывается на 01.07.2026: на дату записки факт отстаёт на три месяца. 2) T = 3 не измерено. 3) k не константа — за 30 месяцев вырос с 0,779 до 0,875, и уровень, посчитанный по k одной даты, стареет вместе с ним. 4) П. 26 Стратегии о трёх пределах уровня рисков дословно не разобран, поэтому разметка зон — наше предложение, а не соответствие ВНД.
A15: Чего книга не доказывает | B15: Что формулы верны по существу. Она доказывает ровно одно: числа получены из ряда объявленными формулами, а допущения формулы буфера проверены на этом же ряде и не отвергнуты. Верна ли метрика и тот ли это ряд — из воспроизводимости не следует.

Sheet Ряд
A1: Ряд топ-20: 36 месячных точек, 01.08.2023 — 01.07.2026
A2: Источник: data/top20_monthly_2023_08_2026_07.csv, дамп листа Monthly рабочей книги 08.09.2026 (DECOMPOSITION § 11.7). Колонки A–D — как в выгрузке, E–M — расчёт. С 01.02.2026 регуляторный капитал в выгрузке отсутствует: метрика ведётся только в балансовой базе, поэтому C, E, F и I у последних шести дат пусты. Это не пропуск данных, а следствие смены базы (Г26).
A4: Дата | B4: Займ топ-20, млн ₸ | C4: СК регуляторный, млн ₸ | D4: СК балансовый, млн ₸ | E4: coef_reg (доля) | F4: v_reg = coef_reg × 100 | G4: coef_new (доля) | H4: v_new = coef_new × 100 | I4: Разрыв баз: v_new − v_reg | J4: Δ = v_new(t) − v_new(t−1) | K4: ΔСК балансовый, % | L4: ΔЗайм, % | M4: Триггер
A5: 2023-08-01 | B5: 323730.9 | C5: 413937.12 | D5: 322505.42 | E5: =IF(C5="","",B5/C5) | F5: =IF(E5="","",E5*100) | G5: =B5/D5 | H5: =G5*100 | I5: =IF(F5="","",H5-F5) | J5: — | K5: — | L5: — | M5: —
A6: 2023-09-01 | B6: 323218.4 | C6: 422472.24 | D6: 331426.59 | E6: =IF(C6="","",B6/C6) | F6: =IF(E6="","",E6*100) | G6: =B6/D6 | H6: =G6*100 | I6: =IF(F6="","",H6-F6) | J6: =H6-H5 | K6: =(D6-D5)/D5*100 | L6: =(B6-B5)/B5*100 | M6: =IF(AND(K6<=por_sk,L6>=por_zaim),"оба",IF(K6<=por_sk,"СК",IF(L6>=por_zaim,"Займ","")))
A7: 2023-10-01 | B7: 327285 | C7: 429717.91 | D7: 339057.93 | E7: =IF(C7="","",B7/C7) | F7: =IF(E7="","",E7*100) | G7: =B7/D7 | H7: =G7*100 | I7: =IF(F7="","",H7-F7) | J7: =H7-H6 | K7: =(D7-D6)/D6*100 | L7: =(B7-B6)/B6*100 | M7: =IF(AND(K7<=por_sk,L7>=por_zaim),"оба",IF(K7<=por_sk,"СК",IF(L7>=por_zaim,"Займ","")))
A8: 2023-11-01 | B8: 338817.1 | C8: 438451.72 | D8: 348167.43 | E8: =IF(C8="","",B8/C8) | F8: =IF(E8="","",E8*100) | G8: =B8/D8 | H8: =G8*100 | I8: =IF(F8="","",H8-F8) | J8: =H8-H7 | K8: =(D8-D7)/D7*100 | L8: =(B8-B7)/B7*100 | M8: =IF(AND(K8<=por_sk,L8>=por_zaim),"оба",IF(K8<=por_sk,"СК",IF(L8>=por_zaim,"Займ","")))
A9: 2023-12-01 | B9: 343497.7 | C9: 443261.61 | D9: 353304.97 | E9: =IF(C9="","",B9/C9) | F9: =IF(E9="","",E9*100) | G9: =B9/D9 | H9: =G9*100 | I9: =IF(F9="","",H9-F9) | J9: =H9-H8 | K9: =(D9-D8)/D8*100 | L9: =(B9-B8)/B8*100 | M9: =IF(AND(K9<=por_sk,L9>=por_zaim),"оба",IF(K9<=por_sk,"СК",IF(L9>=por_zaim,"Займ","")))
A10: 2024-01-01 | B10: 372019.3 | C10: 440898.15 | D10: 351291.9 | E10: =IF(C10="","",B10/C10) | F10: =IF(E10="","",E10*100) | G10: =B10/D10 | H10: =G10*100 | I10: =IF(F10="","",H10-F10) | J10: =H10-H9 | K10: =(D10-D9)/D9*100 | L10: =(B10-B9)/B9*100 | M10: =IF(AND(K10<=por_sk,L10>=por_zaim),"оба",IF(K10<=por_sk,"СК",IF(L10>=por_zaim,"Займ","")))
A11: 2024-02-01 | B11: 359821.6 | C11: 453740.46 | D11: 364498.16 | E11: =IF(C11="","",B11/C11) | F11: =IF(E11="","",E11*100) | G11: =B11/D11 | H11: =G11*100 | I11: =IF(F11="","",H11-F11) | J11: =H11-H10 | K11: =(D11-D10)/D10*100 | L11: =(B11-B10)/B10*100 | M11: =IF(AND(K11<=por_sk,L11>=por_zaim),"оба",IF(K11<=por_sk,"СК",IF(L11>=por_zaim,"Займ","")))
A12: 2024-03-01 | B12: 371215.4 | C12: 472963.53 | D12: 384072.88 | E12: =IF(C12="","",B12/C12) | F12: =IF(E12="","",E12*100) | G12: =B12/D12 | H12: =G12*100 | I12: =IF(F12="","",H12-F12) | J12: =H12-H11 | K12: =(D12-D11)/D11*100 | L12: =(B12-B11)/B11*100 | M12: =IF(AND(K12<=por_sk,L12>=por_zaim),"оба",IF(K12<=por_sk,"СК",IF(L12>=por_zaim,"Займ","")))
A13: 2024-04-01 | B13: 363473 | C13: 484711.53 | D13: 396208.88 | E13: =IF(C13="","",B13/C13) | F13: =IF(E13="","",E13*100) | G13: =B13/D13 | H13: =G13*100 | I13: =IF(F13="","",H13-F13) | J13: =H13-H12 | K13: =(D13-D12)/D12*100 | L13: =(B13-B12)/B12*100 | M13: =IF(AND(K13<=por_sk,L13>=por_zaim),"оба",IF(K13<=por_sk,"СК",IF(L13>=por_zaim,"Займ","")))
A14: 2024-05-01 | B14: 357665.7 | C14: 489303.47 | D14: 401188.39 | E14: =IF(C14="","",B14/C14) | F14: =IF(E14="","",E14*100) | G14: =B14/D14 | H14: =G14*100 | I14: =IF(F14="","",H14-F14) | J14: =H14-H13 | K14: =(D14-D13)/D13*100 | L14: =(B14-B13)/B13*100 | M14: =IF(AND(K14<=por_sk,L14>=por_zaim),"оба",IF(K14<=por_sk,"СК",IF(L14>=por_zaim,"Займ","")))
A15: 2024-06-01 | B15: 360756.5 | C15: 491481.95 | D15: 403780.01 | E15: =IF(C15="","",B15/C15) | F15: =IF(E15="","",E15*100) | G15: =B15/D15 | H15: =G15*100 | I15: =IF(F15="","",H15-F15) | J15: =H15-H14 | K15: =(D15-D14)/D14*100 | L15: =(B15-B14)/B14*100 | M15: =IF(AND(K15<=por_sk,L15>=por_zaim),"оба",IF(K15<=por_sk,"СК",IF(L15>=por_zaim,"Займ","")))
A16: 2024-07-01 | B16: 362413.9 | C16: 492537.19 | D16: 405247.49 | E16: =IF(C16="","",B16/C16) | F16: =IF(E16="","",E16*100) | G16: =B16/D16 | H16: =G16*100 | I16: =IF(F16="","",H16-F16) | J16: =H16-H15 | K16: =(D16-D15)/D15*100 | L16: =(B16-B15)/B15*100 | M16: =IF(AND(K16<=por_sk,L16>=por_zaim),"оба",IF(K16<=por_sk,"СК",IF(L16>=por_zaim,"Займ","")))
A17: 2024-08-01 | B17: 358163.4 | C17: 504710.47 | D17: 417859.74 | E17: =IF(C17="","",B17/C17) | F17: =IF(E17="","",E17*100) | G17: =B17/D17 | H17: =G17*100 | I17: =IF(F17="","",H17-F17) | J17: =H17-H16 | K17: =(D17-D16)/D16*100 | L17: =(B17-B16)/B16*100 | M17: =IF(AND(K17<=por_sk,L17>=por_zaim),"оба",IF(K17<=por_sk,"СК",IF(L17>=por_zaim,"Займ","")))
... A34: 2026-01-01 | B34: 421717.7 | C34: 503086.11 | D34: 439961.27 | E34: =IF(C34="","",B34/C34) | F34: =IF(E34="","",E34*100) | G34: =B34/D34 | H34: =G34*100 | I34: =IF(F34="","",H34-F34) | J34: =H34-H33 | K34: =(D34-D33)/D33*100 | L34: =(B34-B33)/B33*100 | M34: =IF(AND(K34<=por_sk,L34>=por_zaim),"оба",IF(K34<=por_sk,"СК",IF(L34>=por_zaim,"Займ","")))
A35: 2026-02-01 | B35: 393670.5 | D35: 440063.85 | E35: =IF(C35="","",B35/C35) | F35: =IF(E35="","",E35*100) | G35: =B35/D35 | H35: =G35*100 | I35: =IF(F35="","",H35-F35) | J35: =H35-H34 | K35: =(D35-D34)/D34*100 | L35: =(B35-B34)/B34*100 | M35: =IF(AND(K35<=por_sk,L35>=por_zaim),"оба",IF(K35<=por_sk,"СК",IF(L35>=por_zaim,"Займ","")))
A36: 2026-03-01 | B36: 395281.7 | D36: 449623.8 | E36: =IF(C36="","",B36/C36) | F36: =IF(E36="","",E36*100) | G36: =B36/D36 | H36: =G36*100 | I36: =IF(F36="","",H36-F36) | J36: =H36-H35 | K36: =(D36-D35)/D35*100 | L36: =(B36-B35)/B35*100 | M36: =IF(AND(K36<=por_sk,L36>=por_zaim),"оба",IF(K36<=por_sk,"СК",IF(L36>=por_zaim,"Займ","")))
A37: 2026-04-01 | B37: 416607.1 | D37: 446679.83 | E37: =IF(C37="","",B37/C37) | F37: =IF(E37="","",E37*100) | G37: =B37/D37 | H37: =G37*100 | I37: =IF(F37="","",H37-F37) | J37: =H37-H36 | K37: =(D37-D36)/D36*100 | L37: =(B37-B36)/B36*100 | M37: =IF(AND(K37<=por_sk,L37>=por_zaim),"оба",IF(K37<=por_sk,"СК",IF(L37>=por_zaim,"Займ","")))
A38: 2026-05-01 | B38: 439754.5 | D38: 446857.15 | E38: =IF(C38="","",B38/C38) | F38: =IF(E38="","",E38*100) | G38: =B38/D38 | H38: =G38*100 | I38: =IF(F38="","",H38-F38) | J38: =H38-H37 | K38: =(D38-D37)/D37*100 | L38: =(B38-B37)/B37*100 | M38: =IF(AND(K38<=por_sk,L38>=por_zaim),"оба",IF(K38<=por_sk,"СК",IF(L38>=por_zaim,"Займ","")))
A39: 2026-06-01 | B39: 444048.8 | D39: 440316.78 | E39: =IF(C39="","",B39/C39) | F39: =IF(E39="","",E39*100) | G39: =B39/D39 | H39: =G39*100 | I39: =IF(F39="","",H39-F39) | J39: =H39-H38 | K39: =(D39-D38)/D38*100 | L39: =(B39-B38)/B38*100 | M39: =IF(AND(K39<=por_sk,L39>=por_zaim),"оба",IF(K39<=por_sk,"СК",IF(L39>=por_zaim,"Займ","")))
A40: 2026-07-01 | B40: 448999.7 | D40: 442346.33 | E40: =IF(C40="","",B40/C40) | F40: =IF(E40="","",E40*100) | G40: =B40/D40 | H40: =G40*100 | I40: =IF(F40="","",H40-F40) | J40: =H40-H39 | K40: =(D40-D39)/D39*100 | L40: =(B40-B39)/B39*100 | M40: =IF(AND(K40<=por_sk,L40>=por_zaim),"оба",IF(K40<=por_sk,"СК",IF(L40>=por_zaim,"Займ","")))
A42: Колонка I — разрыв двух баз на одну дату, а не движение во времени. Через неё видно, что k не постоянен: разрыв сузился с 22,2 пп в 08.2023 до 12,0 пп в 01.2026. Уровень L = L_рег / k, посчитанный по k одной даты, стареет вместе с k — открытый вопрос к запросу данных, не свойство расчёта.

Sheet Параметры
A1: Параметры расчёта
A2: Всё, что не выводится из ряда. Меняется здесь — пересчитывается везде.
A4: Параметр | B4: Обозначение | C4: Значение | D4: Формула | E4: Откуда
A5: Доверие для буфера | B5: p | C5: 0.9 | D5: ввод | E5: Доля T-месячных движений, которые буфер обязан накрыть. 0,90 означает один ложный отбой из десяти. Это РЕШЕНИЕ комитета о цене ложного сигнала, а не расчётная величина: выше p — жёлтая ниже, лампа горит чаще
A6: Квантиль нормального | B6: z(p) | C6: =NORMSINV(C5) | D6: NORMSINV(p) | E6: Вычисляется из p, не вбивается. По-русски функция называется НОРМСТОБР
A7: Отношение баз капитала | B7: k (Г26) | C7: =Ряд!D34/Ряд!C34 | D7: Ряд!D34/Ряд!C34 | E7: СК_балансовый / СК_регуляторный на 01.01.2026 — последняя дата, где есть обе базы. Находка Г26: с 01.01.2026 знаменатель метрики сменил базу, уровень при этом не пересматривался. ВНИМАНИЕ: k не константа, см. колонку I листа «Ряд»
A8: Уровень в регуляторной базе | B8: L_рег | C8: 95 | D8: ввод | E8: Действующий уровень риск-аппетита по топ-20. Приложение № 3 к Политике (VND-02). История уровня: 250 % → 95 %, см. data/top20_limit_history.csv
A9: Длина цикла реагирования, мес. | B9: T | C9: 3 | D9: ввод | E9: ДОПУЩЕНИЕ, не измеренная величина. Пока длина цикла не закреплена в регламенте, метод H держится на ней со слов — DISCLOSURE § 6
A10: Порог триггера по капиталу, % | B10: порог ΔСК | C10: -3 | D10: ввод | E10: Месячное падение СК, при котором наблюдение ускоряется независимо от зоны
A11: Порог триггера по портфелю, % | B11: порог ΔЗайм | C11: 5 | D11: ввод | E11: Месячный рост задолженности топ-20, при котором наблюдение ускоряется
A13: Из семи параметров вычисляются два: z из p и k из ряда. Остальные пять — чьи-то решения, и у каждого должен быть автор. У L_рег он есть (Приложение № 3), у T и двух порогов — нет. T = 3 единственный без внешнего источника: поставьте другое число в C9 — вся книга пересчитается, и станет видно, что требуемый уровень меняется на 1,4–1,5 пп за каждый месяц цикла.

Sheet Расчёт
A1: Расчётный лист: формула, вход, результат
A2: Колонка D считается формулой из листов «Ряд» и «Параметры». Колонка E — то, что напечатано в DECOMPOSITION § 11.10 и DISCLOSURE § 2. Колонка G должна быть «да» во всех строках: иначе опубликованное число разошлось с расчётом.
A4: Показатель | B4: Формула словами | C4: Формула в этой книге | D4: Значение | E4: Опубликовано | F4: Расхождение | G4: Сходится | H4: Где напечатано
A5: 1. База: что даёт сам ряд
A6: σ_Δ — с.к.о. месячных приростов | B6: выборочное с.к.о. (n−1) по всем 35 приростам | C6: STDEV(d) | D6: =STDEV(d) | E6: 4.0667 | F6: =D6-E6 | G6: =IF(ABS(F6)<=0.0000500000,"да","НЕТ") | H6: DISCLOSURE § 2.1
A7: σ уровней (метод М1) | B7: выборочное с.к.о. самих значений ряда, не приростов | C7: STDEV(v) | D7: =STDEV(v) | E7: 6.2201 | F7: =D7-E7 | G7: =IF(ABS(F7)<=0.0000500000,"да","НЕТ") | H7: DISCLOSURE Р-Д1
A8: Текущая точка, 01.07.2026 | B8: последнее значение ряда | C8: Ряд!H40 | D8: =Ряд!H40 | E8: 101.5041 | F8: =D8-E8 | G8: =IF(ABS(F8)<=0.0000500000,"да","НЕТ") | H8: DISCLOSURE § 2.1
A9: Максимум ряда, 01.2024 | B9: наибольшее значение ряда | C9: MAX(v) | D9: =MAX(v) | E9: 105.9003 | F9: =D9-E9 | G9: =IF(ABS(F9)<=0.0000500000,"да","НЕТ") | H9: DISCLOSURE § 2.1
A10: Число точек | B10: сколько наблюдений в ряде | C10: COUNT(v) | D10: =COUNT(v) | E10: 36 | F10: =D10-E10 | G10: =IF(ABS(F10)<=0.5000000000,"да","НЕТ") | H10: DISCLOSURE § 1
A11: 2. Уровень
A12: L — уровень в балансовой базе | B12: действующий уровень 95 %, пересчитанный под балансовый капитал: L_рег / k | C12: L_reg/k_G26 | D12: =L_reg/k_G26 | E12: 108.6304 | F12: =D12-E12 | G12: =IF(ABS(F12)<=0.0000500000,"да","НЕТ") | H12: DISCLOSURE § 2.2
A13: Это одна величина в двух системах измерения, а не два разных лимита. Фраза «пробит лимит 95 % по балансовому капиталу» — категориальная ошибка: числитель берётся из одной базы, знаменатель из другой. Значение 108,6304 стоит на k, посчитанном из ряда; в DISCLOSURE до 14.09.2026 печаталось 108,6298 — та же величина при k, округлённом до пяти знаков.
A14: 3. Запас на реагирование M(T) = z(p) · σ_Δ · √T и жёлтая линия L − M(T)
A15: Запас M(T) при T = 1 | B15: z(p) × σ_Δ × корень из T | C15: z_p*D6*SQRT(1) | D15: =z_p*D6*SQRT(1) | E15: 5.2117 | F15: =D15-E15 | G15: =IF(ABS(F15)<=0.0000500000,"да","НЕТ") | H15: DISCLOSURE § 2.3
A16: Жёлтая линия при T = 1 | B16: L − M(T) | C16: D12-D15 | D16: =D12-D15 | E16: 103.4187 | F16: =D16-E16 | G16: =IF(ABS(F16)<=0.0000500000,"да","НЕТ") | H16: DISCLOSURE § 2.3
A17: Наблюдений выше жёлтой, T = 1 | B17: сколько точек ряда не ниже жёлтой линии | C17: COUNTIF(v,">="&D16) | D17: =COUNTIF(v,">="&D16) | E17: 1 | F17: =D17-E17 | G17: =IF(ABS(F17)<=0.5000000000,"да","НЕТ") | H17: DISCLOSURE § 2.3, Р-Д3
A18: Доля времени выше жёлтой, T = 1 | B18: их доля от 36 наблюдений | C18: COUNTIF(v,">="&D16)/COUNT(v)*100 | D18: =COUNTIF(v,">="&D16)/COUNT(v)*100 | E18: 2.8 | F18: =D18-E18 | G18: =IF(ABS(F18)<=0.0500000000,"да","НЕТ") | H18: DISCLOSURE § 2.3, Р-Д3
A19: Запас M(T) при T = 2 | B19: z(p) × σ_Δ × корень из T | C19: z_p*D6*SQRT(2) | D19: =z_p*D6*SQRT(2) | E19: 7.3705 | F19: =D19-E19 | G19: =IF(ABS(F19)<=0.0000500000,"да","НЕТ") | H19: DISCLOSURE § 2.3
A20: Жёлтая линия при T = 2 | B20: L − M(T) | C20: D12-D19 | D20: =D12-D19 | E20: 101.2599 | F20: =D20-E20 | G20: =IF(ABS(F20)<=0.0000500000,"да","НЕТ") | H20: DISCLOSURE § 2.3
A21: Наблюдений выше жёлтой, T = 2 | B21: сколько точек ряда не ниже жёлтой линии | C21: COUNTIF(v,">="&D20) | D21: =COUNTIF(v,">="&D20) | E21: 2 | F21: =D21-E21 | G21: =IF(ABS(F21)<=0.5000000000,"да","НЕТ") | H21: DISCLOSURE § 2.3, Р-Д3
A22: Доля времени выше жёлтой, T = 2 | B22: их доля от 36 наблюдений | C22: COUNTIF(v,">="&D20)/COUNT(v)*100 | D22: =COUNTIF(v,">="&D20)/COUNT(v)*100 | E22: 5.6 | F22: =D22-E22 | G22: =IF(ABS(F22)<=0.0500000000,"да","НЕТ") | H22: DISCLOSURE § 2.3, Р-Д3
A23: Запас M(T) при T = 3 | B23: z(p) × σ_Δ × корень из T | C23: z_p*D6*SQRT(3) | D23: =z_p*D6*SQRT(3) | E23: 9.027 | F23: =D23-E23 | G23: =IF(ABS(F23)<=0.0000500000,"да","НЕТ") | H23: DISCLOSURE § 2.3
A24: Жёлтая линия при T = 3 | B24: L − M(T) | C24: D12-D23 | D24: =D12-D23 | E24: 99.6034 | F24: =D24-E24 | G24: =IF(ABS(F24)<=0.0000500000,"да","НЕТ") | H24: DISCLOSURE § 2.3
A25: Наблюдений выше жёлтой, T = 3 | B25: сколько точек ряда не ниже жёлтой линии | C25: COUNTIF(v,">="&D24) | D25: =COUNTIF(v,">="&D24) | E25: 4 | F25: =D25-E25 | G25: =IF(ABS(F25)<=0.5000000000,"да","НЕТ") | H25: DISCLOSURE § 2.3, Р-Д3
A26: Доля времени выше жёлтой, T = 3 | B26: их доля от 36 наблюдений | C26: COUNTIF(v,">="&D24)/COUNT(v)*100 | D26: =COUNTIF(v,">="&D24)/COUNT(v)*100 | E26: 11.1 | F26: =D26-E26 | G26: =IF(ABS(F26)<=0.0500000000,"да","НЕТ") | H26: DISCLOSURE § 2.3, Р-Д3
A27: Запас M(T) при T = 4 | B27: z(p) × σ_Δ × корень из T | C27: z_p*D6*SQRT(4) | D27: =z_p*D6*SQRT(4) | E27: 10.4235 | F27: =D27-E27 | G27: =IF(ABS(F27)<=0.0000500000,"да","НЕТ") | H27: DISCLOSURE § 2.3
A28: Жёлтая линия при T = 4 | B28: L − M(T) | C28: D12-D27 | D28: =D12-D27 | E28: 98.2069 | F28: =D28-E28 | G28: =IF(ABS(F28)<=0.0000500000,"да","НЕТ") | H28: DISCLOSURE § 2.3
A29: Наблюдений выше жёлтой, T = 4 | B29: сколько точек ряда не ниже жёлтой линии | C29: COUNTIF(v,">="&D28) | D29: =COUNTIF(v,">="&D28) | E29: 6 | F29: =D29-E29 | G29: =IF(ABS(F29)<=0.5000000000,"да","НЕТ") | H29: DISCLOSURE § 2.3, Р-Д3
A30: Доля времени выше жёлтой, T = 4 | B30: их доля от 36 наблюдений | C30: COUNTIF(v,">="&D28)/COUNT(v)*100 | D30: =COUNTIF(v,">="&D28)/COUNT(v)*100 | E30: 16.7 | F30: =D30-E30 | G30: =IF(ABS(F30)<=0.0500000000,"да","НЕТ") | H30: DISCLOSURE § 2.3, Р-Д3
A31: Р-Д3: доля в процентах от 36 наблюдений читается точнее, чем есть. 2,8 % — это одно наблюдение, 11,1 % — четыре. На комитете доля называется только вместе с числом наблюдений, поэтому строка «Наблюдений» стоит выше строки «Доля», а не под ней. Обоснование самой формулы M(T) — на листе «Обоснование M(T)»; разметка зон по этим границам — на листе «Зоны».
A32: 4. Квантили ряда (метод C). Линейная интерполяция между порядковыми статистиками
A33: Квантиль 85 % | B33: значение, ниже которого лежит 85 % ряда | C33: PERCENTILE(v,0.85) | D33: =PERCENTILE(v,0.85) | E33: 98.1887 | F33: =D33-E33 | G33: =IF(ABS(F33)<=0.0000500000,"да","НЕТ") | H33: DISCLOSURE § 2.5
A34: Квантиль 90 % | B34: значение, ниже которого лежит 90 % ряда | C34: PERCENTILE(v,0.90) | D34: =PERCENTILE(v,0.90) | E34: 99.5485 | F34: =D34-E34 | G34: =IF(ABS(F34)<=0.0000500000,"да","НЕТ") | H34: DISCLOSURE § 2.5
A35: Квантиль 95 % | B35: значение, ниже которого лежит 95 % ряда | C35: PERCENTILE(v,0.95) | D35: =PERCENTILE(v,0.95) | E35: 101.0117 | F35: =D35-E35 | G35: =IF(ABS(F35)<=0.0000500000,"да","НЕТ") | H35: DISCLOSURE § 2.5
A36: 5. Два независимых пути к одному уровню
A37: Метод H: квантиль 90 % + запас T = 3 | B37: квантиль₉₀(v) + M(3) | C37: D34+D23 | D37: =D34+D23 | E37: 108.5755 | F37: =D37-E37 | G37: =IF(ABS(F37)<=0.0000500000,"да","НЕТ") | H37: DISCLOSURE § 2.4
A38: Расхождение двух путей | B38: L (пересчёт базы) − H (цикл решения) | C38: D12-D37 | D38: =D12-D37 | E38: 0.0549 | F38: =D38-E38 | G38: =IF(ABS(F38)<=0.0000500000,"да","НЕТ") | H38: DISCLOSURE § 2.4
A39: Главный довод против упрёка «уровень подогнан под факт»: пути не связаны по построению. Первый смотрит на отношение баз капитала, второй — на распределение ряда и длину процесса. Сходятся на 0,05 пп.
A40: 6. Производные метрики
A41: D — расстояние до L, в σ | B41: (L − текущая точка) / σ_Δ | C41: (D12-D8)/D6 | D41: =(D12-D8)/D6 | E41: 1.752 | F41: =D41-E41 | G41: =IF(ABS(F41)<=0.0005000000,"да","НЕТ") | H41: DISCLOSURE § 2.6
...

Sheet Обоснование M(T)
A1: Обоснование формулы M(T) = z(p) · σ_Δ · √T
A2: Формула держится на трёх допущениях: приросты независимы (отсюда √T), распределение суммы близко к нормальному (отсюда z), дрейфа нет. Ниже каждое проверено на нашем же ряде. Колонки J–N — служебные: T-месячные изменения, по которым считаются проверки.
A4: Проверка | B4: Что именно проверяется | C4: Формула в этой книге | D4: Значение | E4: Ожидание | F4: Расхождение | G4: Сходится | H4: Как читать | J4: Изменение за 1 мес. | K4: Изменение за 2 мес. | L4: Изменение за 3 мес. | M4: Изменение за 4 мес. | N4: Изменение за 6 мес.
A5: 1. Независимость приростов — единственное, на чём держится √T | J5: =Ряд!H6-Ряд!H5 | K5: =Ряд!H7-Ряд!H5 | L5: =Ряд!H8-Ряд!H5 | M5: =Ряд!H9-Ряд!H5 | N5: =Ряд!H11-Ряд!H5
A6: Автокорреляция лага 1 | B6: связь прироста с предыдущим приростом | C6: CORREL(Ряд!J7:J40,Ряд!J6:J39) | D6: =CORREL(Ряд!J7:J40,Ряд!J6:J39) | E6: -0.0828 | F6: =D6-E6 | G6: =IF(ABS(F6)<=0.0000500000,"да","НЕТ") | H6: новое, 14.09.2026 | J6: =Ряд!H7-Ряд!H6 | K6: =Ряд!H8-Ряд!H6 | L6: =Ряд!H9-Ряд!H6 | M6: =Ряд!H10-Ряд!H6 | N6: =Ряд!H12-Ряд!H6
A7: Порог значимости 2/√n | B7: выше этого значения автокорреляцию нельзя считать шумом | C7: 2/SQRT(COUNT(d)) | D7: =2/SQRT(COUNT(d)) | E7: 0.3381 | F7: =D7-E7 | G7: =IF(ABS(F7)<=0.0000500000,"да","НЕТ") | H7: новое | J7: =Ряд!H8-Ряд!H7 | K7: =Ряд!H9-Ряд!H7 | L7: =Ряд!H10-Ряд!H7 | M7: =Ряд!H11-Ряд!H7 | N7: =Ряд!H13-Ряд!H7
A8: |−0,083| против порога 0,338 — свидетельств против независимости нет. Это НЕ доказательство независимости: при 35 наблюдениях тест почти лишён мощности. Сказать об этом надо самим, иначе скажет оппонент. | J8: =Ряд!H9-Ряд!H8 | K8: =Ряд!H10-Ряд!H8 | L8: =Ряд!H11-Ряд!H8 | M8: =Ряд!H12-Ряд!H8 | N8: =Ряд!H14-Ряд!H8
A9: Фактическое с.к.о. изменений за 1 мес. | B9: разброс реальных 1-месячных изменений ряда | C9: STDEV($J$5:$J$39) | D9: =STDEV($J$5:$J$39) | E9: 4.0667 | F9: =D9-E9 | G9: =IF(ABS(F9)<=0.0000500000,"да","НЕТ") | H9: новое | J9: =Ряд!H10-Ряд!H9 | K9: =Ряд!H11-Ряд!H9 | L9: =Ряд!H12-Ряд!H9 | M9: =Ряд!H13-Ряд!H9 | N9: =Ряд!H15-Ряд!H9
A10: Отношение факт / модель при T = 1 | B10: во сколько раз реальный разброс отличается от σ_Δ·√1 | C10: D9/('Расчёт'!D6*SQRT(1)) | D10: =D9/('Расчёт'!D6*SQRT(1)) | E10: 1 | F10: =D10-E10 | G10: =IF(ABS(F10)<=0.0000500000,"да","НЕТ") | H10: новое | J10: =Ряд!H11-Ряд!H10 | K10: =Ряд!H12-Ряд!H10 | L10: =Ряд!H13-Ряд!H10 | M10: =Ряд!H14-Ряд!H10 | N10: =Ряд!H16-Ряд!H10
A11: Фактическое с.к.о. изменений за 2 мес. | B11: разброс реальных 2-месячных изменений ряда | C11: STDEV($K$5:$K$38) | D11: =STDEV($K$5:$K$38) | E11: 5.5686 | F11: =D11-E11 | G11: =IF(ABS(F11)<=0.0000500000,"да","НЕТ") | H11: новое | J11: =Ряд!H12-Ряд!H11 | K11: =Ряд!H13-Ряд!H11 | L11: =Ряд!H14-Ряд!H11 | M11: =Ряд!H15-Ряд!H11 | N11: =Ряд!H17-Ряд!H11
A12: Отношение факт / модель при T = 2 | B12: во сколько раз реальный разброс отличается от σ_Δ·√2 | C12: D11/('Расчёт'!D6*SQRT(2)) | D12: =D11/('Расчёт'!D6*SQRT(2)) | E12: 0.9682 | F12: =D12-E12 | G12: =IF(ABS(F12)<=0.0000500000,"да","НЕТ") | H12: новое | J12: =Ряд!H13-Ряд!H12 | K12: =Ряд!H14-Ряд!H12 | L12: =Ряд!H15-Ряд!H12 | M12: =Ряд!H16-Ряд!H12 | N12: =Ряд!H18-Ряд!H12
A13: Фактическое с.к.о. изменений за 3 мес. | B13: разброс реальных 3-месячных изменений ряда | C13: STDEV($L$5:$L$37) | D13: =STDEV($L$5:$L$37) | E13: 6.4021 | F13: =D13-E13 | G13: =IF(ABS(F13)<=0.0000500000,"да","НЕТ") | H13: новое | J13: =Ряд!H14-Ряд!H13 | K13: =Ряд!H15-Ряд!H13 | L13: =Ряд!H16-Ряд!H13 | M13: =Ряд!H17-Ряд!H13 | N13: =Ряд!H19-Ряд!H13
A14: Отношение факт / модель при T = 3 | B14: во сколько раз реальный разброс отличается от σ_Δ·√3 | C14: D13/('Расчёт'!D6*SQRT(3)) | D14: =D13/('Расчёт'!D6*SQRT(3)) | E14: 0.9089 | F14: =D14-E14 | G14: =IF(ABS(F14)<=0.0000500000,"да","НЕТ") | H14: новое | J14: =Ряд!H15-Ряд!H14 | K14: =Ряд!H16-Ряд!H14 | L14: =Ряд!H17-Ряд!H14 | M14: =Ряд!H18-Ряд!H14 | N14: =Ряд!H20-Ряд!H14
A15: Фактическое с.к.о. изменений за 4 мес. | B15: разброс реальных 4-месячных изменений ряда | C15: STDEV($M$5:$M$36) | D15: =STDEV($M$5:$M$36) | E15: 7.1177 | F15: =D15-E15 | G15: =IF(ABS(F15)<=0.0000500000,"да","НЕТ") | H15: новое | J15: =Ряд!H16-Ряд!H15 | K15: =Ряд!H17-Ряд!H15 | L15: =Ряд!H18-Ряд!H15 | M15: =Ряд!H19-Ряд!H15 | N15: =Ряд!H21-Ряд!H15
A16: Отношение факт / модель при T = 4 | B16: во сколько раз реальный разброс отличается от σ_Δ·√4 | C16: D15/('Расчёт'!D6*SQRT(4)) | D16: =D15/('Расчёт'!D6*SQRT(4)) | E16: 0.8751 | F16: =D16-E16 | G16: =IF(ABS(F16)<=0.0000500000,"да","НЕТ") | H16: новое | J16: =Ряд!H17-Ряд!H16 | K16: =Ряд!H18-Ряд!H16 | L16: =Ряд!H19-Ряд!H16 | M16: =Ряд!H20-Ряд!H16 | N16: =Ряд!H22-Ряд!H16
A17: Фактическое с.к.о. изменений за 6 мес. | B17: разброс реальных 6-месячных изменений ряда | C17: STDEV($N$5:$N$34) | D17: =STDEV($N$5:$N$34) | E17: 7.694 | F17: =D17-E17 | G17: =IF(ABS(F17)<=0.0000500000,"да","НЕТ") | H17: новое | J17: =Ряд!H18-Ряд!H17 | K17: =Ряд!H19-Ряд!H17 | L17: =Ряд!H20-Ряд!H17 | M17: =Ряд!H21-Ряд!H17 | N17: =Ряд!H23-Ряд!H17
A18: Отношение факт / модель при T = 6 | B18: во сколько раз реальный разброс отличается от σ_Δ·√6 | C18: D17/('Расчёт'!D6*SQRT(6)) | D18: =D17/('Расчёт'!D6*SQRT(6)) | E18: 0.7724 | F18: =D18-E18 | G18: =IF(ABS(F18)<=0.0000500000,"да","НЕТ") | H18: новое | J18: =Ряд!H19-Ряд!H18 | K18: =Ряд!H20-Ряд!H18 | L18: =Ряд!H21-Ряд!H18 | M18: =Ряд!H22-Ряд!H18 | N18: =Ряд!H24-Ряд!H18
A19: Отношение ниже единицы означает, что √T ЗАВЫШАЕТ разброс: ряд слегка возвращается к среднему. На T = 3 завышение 9 %, на T = 6 — 23 %. Для буфера это ошибка в безопасную сторону — жёлтая линия ниже, предупреждение раньше. Оговорка: окна перекрываются, поэтому это оценка, а не точное измерение. | J19: =Ряд!H20-Ряд!H19 | K19: =Ряд!H21-Ряд!H19 | L19: =Ряд!H22-Ряд!H19 | M19: =Ряд!H23-Ряд!H19 | N19: =Ряд!H25-Ряд!H19
A20: 2. Нормальность — и почему нужна не та, о которой спрашивают | J20: =Ряд!H21-Ряд!H20 | K20: =Ряд!H22-Ряд!H20 | L20: =Ряд!H23-Ряд!H20 | M20: =Ряд!H24-Ряд!H20 | N20: =Ряд!H26-Ряд!H20
A21: Асимметрия приростов | B21: скошенность месячных приростов: третий момент / σ³ | C21: (SUMPRODUCT((d-AVERAGE(d))^3)/COUNT(d))/(SUMPRODUCT((d-AVERAGE(d))^2)/COUNT(d))^1.5 | D21: =(SUMPRODUCT((d-AVERAGE(d))^3)/COUNT(d))/(SUMPRODUCT((d-AVERAGE(d))^2)/COUNT(d))^1.5 | E21: 0.6738 | F21: =D21-E21 | G21: =IF(ABS(F21)<=0.0000500000,"да","НЕТ") | H21: новое | J21: =Ряд!H22-Ряд!H21 | K21: =Ряд!H23-Ряд!H21 | L21: =Ряд!H24-Ряд!H21 | M21: =Ряд!H25-Ряд!H21 | N21: =Ряд!H27-Ряд!H21
A22: Избыточный эксцесс приростов | B22: толщина хвостов приростов: четвёртый момент / σ⁴ − 3 | C22: (SUMPRODUCT((d-AVERAGE(d))^4)/COUNT(d))/(SUMPRODUCT((d-AVERAGE(d))^2)/COUNT(d))^2-3 | D22: =(SUMPRODUCT((d-AVERAGE(d))^4)/COUNT(d))/(SUMPRODUCT((d-AVERAGE(d))^2)/COUNT(d))^2-3 | E22: 0.1896 | F22: =D22-E22 | G22: =IF(ABS(F22)<=0.0000500000,"да","НЕТ") | H22: новое | J22: =Ряд!H23-Ряд!H22 | K22: =Ряд!H24-Ряд!H22 | L22: =Ряд!H25-Ряд!H22 | M22: =Ряд!H26-Ряд!H22 | N22: =Ряд!H28-Ряд!H22
A23: Жарк–Бера по приростам | B23: сводный тест нормальности: n/6 × (g1² + g2²/4) | C23: COUNT(d)/6*(D21^2+D22^2/4) | D23: =COUNT(d)/6*(D21^2+D22^2/4) | E23: 2.7009 | F23: =D23-E23 | G23: =IF(ABS(F23)<=0.0000500000,"да","НЕТ") | H23: новое | J23: =Ряд!H24-Ряд!H23 | K23: =Ряд!H25-Ряд!H23 | L23: =Ряд!H26-Ряд!H23 | M23: =Ряд!H27-Ряд!H23 | N23: =Ряд!H29-Ряд!H23
A24: Критическое значение 5 % | B24: порог хи-квадрат с 2 степенями свободы; выше него нормальность отвергается | C24: 5.991 | D24: =5.991 | E24: 5.991 | F24: =D24-E24 | G24: =IF(ABS(F24)<=0.0005000000,"да","НЕТ") | H24: статистическая таблица | J24: =Ряд!H25-Ряд!H24 | K24: =Ряд!H26-Ряд!H24 | L24: =Ряд!H27-Ряд!H24 | M24: =Ряд!H28-Ряд!H24 | N24: =Ряд!H30-Ряд!H24
A25: Асимметрия 3-месячных изменений | B25: скошенность того, к чему буфер реально применяется | C25: (SUMPRODUCT(($L$5:$L$37-AVERAGE($L$5:$L$37))^3)/COUNT($L$5:$L$37))/(SUMPRODUCT(($L$5:$L$37-AVERAGE($L$5:$L$37))^2)/COUNT($L$5:$L$37))^1.5 | D25: =(SUMPRODUCT(($L$5:$L$37-AVERAGE($L$5:$L$37))^3)/COUNT($L$5:$L$37))/(SUMPRODUCT(($L$5:$L$37-AVERAGE($L$5:$L$37))^2)/COUNT($L$5:$L$37))^1.5 | E25: 0.0448 | F25: =D25-E25 | G25: =IF(ABS(F25)<=0.0000500000,"да","НЕТ") | H25: новое | J25: =Ряд!H26-Ряд!H25 | K25: =Ряд!H27-Ряд!H25 | L25: =Ряд!H28-Ряд!H25 | M25: =Ряд!H29-Ряд!H25 | N25: =Ряд!H31-Ряд!H25
A26: Избыточный эксцесс 3-месячных изменений | B26: толщина хвостов трёхмесячной суммы | C26: (SUMPRODUCT(($L$5:$L$37-AVERAGE($L$5:$L$37))^4)/COUNT($L$5:$L$37))/(SUMPRODUCT(($L$5:$L$37-AVERAGE($L$5:$L$37))^2)/COUNT($L$5:$L$37))^2-3 | D26: =(SUMPRODUCT(($L$5:$L$37-AVERAGE($L$5:$L$37))^4)/COUNT($L$5:$L$37))/(SUMPRODUCT(($L$5:$L$37-AVERAGE($L$5:$L$37))^2)/COUNT($L$5:$L$37))^2-3 | E26: -0.4373 | F26: =D26-E26 | G26: =IF(ABS(F26)<=0.0000500000,"да","НЕТ") | H26: новое | J26: =Ряд!H27-Ряд!H26 | K26: =Ряд!H28-Ряд!H26 | L26: =Ряд!H29-Ряд!H26 | M26: =Ряд!H30-Ряд!H26 | N26: =Ряд!H32-Ряд!H26
A27: Жарк–Бера по 3-месячным изменениям | B27: тот же тест на трёхмесячной сумме | C27: COUNT($L$5:$L$37)/6*(D25^2+D26^2/4) | D27: =COUNT($L$5:$L$37)/6*(D25^2+D26^2/4) | E27: 0.274 | F27: =D27-E27 | G27: =IF(ABS(F27)<=0.0000500000,"да","НЕТ") | H27: новое | J27: =Ряд!H28-Ряд!H27 | K27: =Ряд!H29-Ряд!H27 | L27: =Ряд!H30-Ряд!H27 | M27: =Ряд!H31-Ряд!H27 | N27: =Ряд!H33-Ряд!H27
A28: Что предсказывает ЦПТ | B28: асимметрия суммы трёх независимых = g1 / √3 | C28: D21/SQRT(3) | D28: =D21/SQRT(3) | E28: 0.389 | F28: =D28-E28 | G28: =IF(ABS(F28)<=0.0000500000,"да","НЕТ") | H28: новое | J28: =Ряд!H29-Ряд!H28 | K28: =Ряд!H30-Ряд!H28 | L28: =Ряд!H31-Ряд!H28 | M28: =Ряд!H32-Ряд!H28 | N28: =Ряд!H34-Ряд!H28
A29: Главный довод: буфер применяется не к приростам, а к их трёхмесячной СУММЕ. У приростов асимметрия 0,67 — заметная. У трёхмесячной суммы 0,04, то есть она исчезла, и даже быстрее, чем требовала ЦПТ (0,39). Жарк–Бера 2,70 против критических 5,99 — нормальность не отвергается даже на приростах. И третье: z(0,90) = 1,28 лежит в теле распределения, а не в хвосте; ошибки нормальности бьют на 99 % и 99,9 %, а не на 90 %. | J29: =Ряд!H30-Ряд!H29 | K29: =Ряд!H31-Ряд!H29 | L29: =Ряд!H32-Ряд!H29 | M29: =Ряд!H33-Ряд!H29 | N29: =Ряд!H35-Ряд!H29
A30: 3. Буфер M(3) четырьмя независимыми способами | J30: =Ряд!H31-Ряд!H30 | K30: =Ряд!H32-Ряд!H30 | L30: =Ряд!H33-Ряд!H30 | M30: =Ряд!H34-Ряд!H30 | N30: =Ряд!H36-Ряд!H30
A31: Нормальная модель z·σ_Δ·√3 | B31: то, что стоит в расчёте | C31: z_p*'Расчёт'!D6*SQRT(3) | D31: =z_p*'Расчёт'!D6*SQRT(3) | E31: 9.027 | F31: =D31-E31 | G31: =IF(ABS(F31)<=0.0000500000,"да","НЕТ") | H31: DISCLOSURE § 2.3 | J31: =Ряд!H32-Ряд!H31 | K31: =Ряд!H33-Ряд!H31 | L31: =Ряд!H34-Ряд!H31 | M31: =Ряд!H35-Ряд!H31 | N31: =Ряд!H37-Ряд!H31
A32: Эмпирический 90-й процентиль | B32: 90 % реальных 3-месячных изменений не превысили эту величину | C32: PERCENTILE($L$5:$L$37,p_conf) | D32: =PERCENTILE($L$5:$L$37,p_conf) | E32: 9.2887 | F32: =D32-E32 | G32: =IF(ABS(F32)<=0.0000500000,"да","НЕТ") | H32: новое | J32: =Ряд!H33-Ряд!H32 | K32: =Ряд!H34-Ряд!H32 | L32: =Ряд!H35-Ряд!H32 | M32: =Ряд!H36-Ряд!H32 | N32: =Ряд!H38-Ряд!H32
A33: Корниш–Фишер | B33: нормальный квантиль с поправкой на асимметрию и эксцесс суммы | C33: (z_p+(z_p^2-1)/6*D21/SQRT(3)+(z_p^3-3*z_p)/24*D22/3-(2*z_p^3-5*z_p)/36*(D21/SQRT(3))^2)*'Расчёт'!D6*SQRT(3) | D33: =(z_p+(z_p^2-1)/6*D21/SQRT(3)+(z_p^3-3*z_p)/24*D22/3-(2*z_p^3-5*z_p)/36*(D21/SQRT(3))^2)*'Расчёт'!D6*SQRT(3) | E33: 9.3532 | F33: =D33-E33 | G33: =IF(ABS(F33)<=0.0000500000,"да","НЕТ") | H33: новое | J33: =Ряд!H34-Ряд!H33 | K33: =Ряд!H35-Ряд!H33 | L33: =Ряд!H36-Ряд!H33 | M33: =Ряд!H37-Ряд!H33 | N33: =Ряд!H39-Ряд!H33
A34: Разброс трёх способов, % | B34: насколько максимальный ответ выше минимального | C34: MAX(D31,D32,D33)/MIN(D31,D32,D33)*100-100 | D34: =MAX(D31,D32,D33)/MIN(D31,D32,D33)*100-100 | E34: 3.6137 | F34: =D34-E34 | G34: =IF(ABS(F34)<=0.0000500000,"да","НЕТ") | H34: новое | J34: =Ряд!H35-Ряд!H34 | K34: =Ряд!H36-Ряд!H34 | L34: =Ряд!H37-Ряд!H34 | M34: =Ряд!H38-Ряд!H34 | N34: =Ряд!H40-Ряд!H34
A35: Стандартная ошибка самой σ_Δ | B35: точность оценки σ по 35 наблюдениям: σ / √(2(n−1)) | C35: 'Расчёт'!D6/SQRT(2*(COUNT(d)-1)) | D35: ='Расчёт'!D6/SQRT(2*(COUNT(d)-1)) | E35: 0.4932 | F35: =D35-E35 | G35: =IF(ABS(F35)<=0.0000500000,"да","НЕТ") | H35: новое | J35: =Ряд!H36-Ряд!H35 | K35: =Ряд!H37-Ряд!H35 | L35: =Ряд!H38-Ряд!H35 | M35: =Ряд!H39-Ряд!H35
A36: Она же в единицах M(3) | B36: z · SE(σ) · √3 — неопределённость буфера | C36: z_p*D35*SQRT(3) | D36: =z_p*D35*SQRT(3) | E36: 1.0947 | F36: =D36-E36 | G36: =IF(ABS(F36)<=0.0000500000,"да","НЕТ") | H36: новое | J36: =Ряд!H37-Ряд!H36 | K36: =Ряд!H38-Ряд!H36 | L36: =Ряд!H39-Ряд!H36 | M36: =Ряд!H40-Ряд!H36
A37: Все три непараметрических способа дают буфер ВЫШЕ нормальной модели, разброс 3,6 %. Направление систематическое: нормальная модель тонковата примерно на 0,33 пп. Поправка сознательно не вносится — собственная погрешность σ_Δ равна ±1,09 пп, то есть втрое больше смещения. Но записано это должно быть явно: ровно за молчание о выборе σ мы критикуем метод B в Р-Д1. Четвёртый способ — бутстрап 200 тыс. сумм трёх случайно взятых приростов — даёт 9,3688; в Excel без макросов он не воспроизводится и потому в таблицу не вынесен. | J37: =Ряд!H38-Ряд!H37 | K37: =Ряд!H39-Ряд!H37 | L37: =Ряд!H40-Ряд!H37
A38: 4. Дрейф | J38: =Ряд!H39-Ряд!H38 | K38: =Ряд!H40-Ряд!H38
A39: Средний прирост за месяц | B39: есть ли систематический снос ряда вверх | C39: AVERAGE(d) | D39: =AVERAGE(d) | E39: 0.0321 | F39: =D39-E39 | G39: =IF(ABS(F39)<=0.0000500000,"да","НЕТ") | H39: новое | J39: =Ряд!H40-Ряд!H39
A40: Дрейф за 3 месяца | B40: во что он превращается на горизонте буфера | C40: AVERAGE(d)*3 | D40: =AVERAGE(d)*3 | E40: 0.0964 | F40: =D40-E40 | G40: =IF(ABS(F40)<=0.0000500000,"да","НЕТ") | H40: новое
A41: 0,10 пп против буфера 9,03 — меньше 1 %. Допущение нулевого дрейфа безвредно, слагаемое μ·T в формулу не добавляется.
...

Sheet Зоны
A1: Зоны: зелёная, жёлтая, красная
A2: Границы зон — не подобранные числа, а одна и та же формула L − M(T) при разном T. Поэтому зона читается как ОСТАТОК ВРЕМЕНИ до лимита, а не как цвет.
A4: Зона | B4: Что означает | C4: Нижняя граница | D4: Верхняя граница | E4: Наблюдений | F4: Доля, % | G4: Что делает
A5: Зелёная | B5: больше трёх месяцев запаса | C5: — | D5: ='Расчёт'!D24 | E5: =COUNTIF(v,"<"&'Расчёт'!D24) | F5: =E5/COUNT(v)*100 | G5: Штатное наблюдение: ежемесячный отчёт, без отдельных действий
A6: Жёлтая | B6: от одного до трёх месяцев | C6: ='Расчёт'!D24 | D6: ='Расчёт'!D16 | E6: =COUNTIFS(v,">="&'Расчёт'!D24,v,"<"&'Расчёт'!D16) | F6: =E6/COUNT(v)*100 | G6: Ускоренное наблюдение и заранее согласованные меры. Времени на решение ещё хватает — в этом весь смысл границы
A7: Красная | B7: меньше месяца либо пробой | C7: ='Расчёт'!D16 | D7: — | E7: =COUNTIF(v,">="&'Расчёт'!D16) | F7: =E7/COUNT(v)*100 | G7: Эскалация на уполномоченный орган. Граница стоит НИЖЕ лимита сознательно: красная лампа, загорающаяся в момент пробоя, не предупреждает, а протоколирует
A8: Всего | E8: =SUM(E5:E7) | F8: =E8/COUNT(v)*100 | G8: Должно быть 36 и 100,0 % — иначе границы зон не покрывают ряд целиком либо перекрываются.
A10: Где мы сейчас
A11: Текущая точка, 01.07.2026 | B11: ='Расчёт'!D8 | C11: 101.5041 | D11: опубликовано
A12: Граница жёлтой (3 мес.) | B12: ='Расчёт'!D24 | C12: 99.6034 | D12: опубликовано
A13: Граница красной (1 мес.) | B13: ='Расчёт'!D16 | C13: 103.4187 | D13: опубликовано
A14: Лимит | B14: ='Расчёт'!D12 | C14: 108.6304 | D14: опубликовано
A15: До лимита, пп | B15: ='Расчёт'!D12-'Расчёт'!D8 | C15: 7.1263 | D15: опубликовано
A16: T* — остаток времени, мес. | B16: ='Расчёт'!D44 | C16: 1.8697 | D16: опубликовано
A17: Зона текущей точки | B17: =IF('Расчёт'!D8>='Расчёт'!D12,"ПРОБОЙ",IF('Расчёт'!D8>='Расчёт'!D16,"КРАСНАЯ",IF('Расчёт'!D8>='Расчёт'!D24,"ЖЁЛТАЯ","ЗЕЛЁНАЯ")))
A19: Красная зона по этой разметке за 36 месяцев загоралась один раз — 01.2024. Пробоев не было ни разу, поэтому метод G (калибровка по историческим превышениям) на этом ряде неприменим: калибровать не на чем.
A20: ОТКРЫТЫЙ ВОПРОС. Стратегия риск-аппетита, п. 26, задаёт «три предела уровня рисков». Разметка выше содержит три зоны и потому с ним совместима — но п. 26 у нас процитирован по карте документов и ДОСЛОВНО НЕ РАЗОБРАН. Пока он не прочитан, эти три зоны являются нашим предложением, а не соответствием ВНД, и заявлять обратное на комитете нельзя.

Sheet Две сигмы
A1: Две σ в одной таблице методов — и они про разное
A2: Остаток находки Р-Д1. Третья σ принадлежала методу B, который из книги убран: он не защищается на комитете. В DISCLOSURE.md Р-Д1 остаётся целиком — там он про чужую опубликованную таблицу, а не про нашу книгу.
A4: Методы | B4: Какая σ | C4: Значение | D4: К σ_Δ | E4: Что из этого следует
A5: D, H | B5: выборочное с.к.о. приростов, все 35 | C5: ='Расчёт'!D6 | D5: =C5/'Расчёт'!D6 | E5: Базовая. На ней стоят запас M(T), расстояние D и T*
A6: М1 | B6: выборочное с.к.о. самих уровней, не приростов | C6: ='Расчёт'!D7 | D6: =C6/'Расчёт'!D6 | E6: Мера разброса уровня за три года, а не месячного хода. С первой несопоставима в принципе: одна про то, где ряд стоял, другая про то, как быстро он движется
A8: Правило, которое из этого остаётся: σ называется прямо в строке метода. Метод, защищаемый в собственных терминах, несравним с методом, защищаемым в своих, — и разница в 53 % между этими двумя σ тому иллюстрация.

Sheet Триггеры
A1: Триггеры на движение: ΔСК ≤ −3 % или ΔЗайм ≥ +5 % за месяц
A2: Срабатывают независимо от зоны. Все 35 приростов показаны целиком — выборка из шести строк недоказуема: по ней не видно, что остальные 29 условию не отвечают.
A4: Дата | B4: ΔСК, % | C4: ΔЗайм, % | D4: Коэффициент | E4: Что сработало
A5: ='Ряд'!A6 | B5: ='Ряд'!K6 | C5: ='Ряд'!L6 | D5: ='Ряд'!H6 | E5: ='Ряд'!M6
A6: ='Ряд'!A7 | B6: ='Ряд'!K7 | C6: ='Ряд'!L7 | D6: ='Ряд'!H7 | E6: ='Ряд'!M7
A7: ='Ряд'!A8 | B7: ='Ряд'!K8 | C7: ='Ряд'!L8 | D7: ='Ряд'!H8 | E7: ='Ряд'!M8
A8: ='Ряд'!A9 | B8: ='Ряд'!K9 | C8: ='Ряд'!L9 | D8: ='Ряд'!H9 | E8: ='Ряд'!M9
A9: ='Ряд'!A10 | B9: ='Ряд'!K10 | C9: ='Ряд'!L10 | D9: ='Ряд'!H10 | E9: ='Ряд'!M10
A10: ='Ряд'!A11 | B10: ='Ряд'!K11 | C10: ='Ряд'!L11 | D10: ='Ряд'!H11 | E10: ='Ряд'!M11
A11: ='Ряд'!A12 | B11: ='Ряд'!K12 | C11: ='Ряд'!L12 | D11: ='Ряд'!H12 | E11: ='Ряд'!M12
A12: ='Ряд'!A13 | B12: ='Ряд'!K13 | C12: ='Ряд'!L13 | D12: ='Ряд'!H13 | E12: ='Ряд'!M13
A13: ='Ряд'!A14 | B13: ='Ряд'!K14 | C13: ='Ряд'!L14 | D13: ='Ряд'!H14 | E13: ='Ряд'!M14
A14: ='Ряд'!A15 | B14: ='Ряд'!K15 | C14: ='Ряд'!L15 | D14: ='Ряд'!H15 | E14: ='Ряд'!M15
A15: ='Ряд'!A16 | B15: ='Ряд'!K16 | C15: ='Ряд'!L16 | D15: ='Ряд'!H16 | E15: ='Ряд'!M16
A16: ='Ряд'!A17 | B16: ='Ряд'!K17 | C16: ='Ряд'!L17 | D16: ='Ряд'!H17 | E16: ='Ряд'!M17
... A39: ='Ряд'!A40 | B39: ='Ряд'!K40 | C39: ='Ряд'!L40 | D39: ='Ряд'!H40 | E39: ='Ряд'!M40
A41: Сработало | B41: =COUNTIF(E5:E39,"Займ")+COUNTIF(E5:E39,"СК")+COUNTIF(E5:E39,"оба") | C41: =B41/35*100 | D41: из 35 приростов, %
A43: Строка 01.2026 — та, ради которой триггеры и заводятся: вход сделан капиталом (ΔСК = −7,92 %), а не портфелем, и уровневая зона его не предупреждала в принципе. Зона смотрит на значение коэффициента, триггер — на его движение. Формула M(T) описывает диффузию, триггер ловит скачок; ни один из двух инструментов не заменяет другой.
