Workbook
Name v: 'Ряд'!$E$5:$E$40
Name d: 'Ряд'!$F$6:$F$40
Name dB: 'Ряд'!$J$6:$J$40
Name z_90: 'Параметры'!$C$5
Name k_G26: 'Параметры'!$C$6
Name L_reg: 'Параметры'!$C$7
Name T_cikl: 'Параметры'!$C$8

Sheet Как защищать
A1: Расчётный лист по топ-20: как им пользоваться на комитете
A2: Собрано 14.09.2026 из data/top20_monthly_2023_08_2026_07.csv. Книга собирается build/raschet_list.py — правки вносятся в скрипт, а не в готовый файл.
A4: Что в книге | B4: Лист «Ряд» — 36 точек и всё, что считается построчно. Лист «Параметры» — четыре входа, которые не выводятся из ряда. Лист «Расчёт» — каждое опубликованное число живой формулой, рядом напечатанное значение и расхождение. Лист «Три сигмы» — ответ на самый неудобный вопрос к таблице методов. Лист «Триггеры» — все 35 приростов, а не выбранные шесть.
A5: Главное свойство | B5: В книге нет ни одного вбитого руками результата. Любое число на слайде выделяется в колонке D листа «Расчёт», и в строке формул видно, из чего оно получено. Если кто-то не согласен с параметром — он меняется на листе «Параметры», и вся книга пересчитывается при нём.
A6: Ответ на «откуда 108,63» | B6: Уровень 95 % задан в регуляторной базе капитала. С 01.01.2026 знаменатель метрики — балансовый капитал (Г26), и k = 0,87453 есть отношение баз. 108,63 — тот же самый уровень, выраженный в новой базе. Второй, независимый путь: квантиль 90 % ряда плюс запас на три месяца даёт 108,58. Сходимость двух путей на 0,05 пп и есть довод, что уровень не подогнан.
A7: Ответ на «почему T = 3» | B7: Честный: длина цикла решения не измерена и в регламенте не закреплена. Это записано как незакрытый пункт, а не спрятано. Поставьте на листе «Параметры» T = 2 или T = 4 — видно, что уровень двигается примерно на 1,4–1,5 пп за месяц цикла, и станет предметен разговор о том, сколько на самом деле занимает решение.
A8: Ответ на «а если ничего не менять» | B8: Лист «Расчёт», блок 7. При сохранении уровня 95 % жёлтая линия ложится на 85,97, и выше неё оказывается 31 наблюдение из 36. Светофор с постоянно горящей лампой не является системой раннего предупреждения.
A9: Три места, где книга слаба — сказать самому | B9: Р-Д1: в таблице методов три разные σ, и у метода B определение восстановлено обратным счётом (лист «Три сигмы»). Р-Д2: ряд обрывается на 01.07.2026, то есть на дату записки 30.09 факт отстаёт на три месяца. Р-Д3: доля времени в процентах от 36 наблюдений читается точнее, чем есть.
A10: Чего книга не доказывает | B10: Что формулы верны по существу. Она доказывает ровно одно: числа получены из ряда объявленными формулами. Верна ли формула, тот ли ряд, та ли метрика — из воспроизводимости не следует.

Sheet Ряд
A1: Ряд топ-20: 36 месячных точек, 01.08.2023 — 01.07.2026
A2: Источник: data/top20_monthly_2023_08_2026_07.csv, дамп листа Monthly рабочей книги 08.09.2026 (DECOMPOSITION § 11.7). Колонки A–D — как в выгрузке, E–K — расчёт.
A4: Дата | B4: Займ топ-20, млн ₸ | C4: СК балансовый, млн ₸ | D4: coef_new (доля) | E4: v = coef_new × 100 | F4: Δ = v(t) − v(t−1) | G4: ΔСК, % | H4: ΔЗайм, % | I4: В базе метода B | J4: Δ для метода B | K4: Триггер
A5: 2023-08-01 | B5: 323730.9 | C5: 322505.42 | D5: 1.0037999 | E5: =D5*100 | F5: — | G5: — | H5: — | I5: — | J5: — | K5: —
A6: 2023-09-01 | B6: 323218.4 | C6: 331426.59 | D6: 0.97523376 | E6: =D6*100 | F6: =E6-E5 | G6: =(C6-C5)/C5*100 | H6: =(B6-B5)/B5*100 | I6: 1 | J6: =IF(I6=1,F6,"") | K6: =IF(AND(G6<=-3,H6>=5),"оба",IF(G6<=-3,"СК",IF(H6>=5,"Займ","")))
A7: 2023-10-01 | B7: 327285 | C7: 339057.93 | D7: 0.96527752 | E7: =D7*100 | F7: =E7-E6 | G7: =(C7-C6)/C6*100 | H7: =(B7-B6)/B6*100 | I7: 1 | J7: =IF(I7=1,F7,"") | K7: =IF(AND(G7<=-3,H7>=5),"оба",IF(G7<=-3,"СК",IF(H7>=5,"Займ","")))
A8: 2023-11-01 | B8: 338817.1 | C8: 348167.43 | D8: 0.97314415 | E8: =D8*100 | F8: =E8-E7 | G8: =(C8-C7)/C7*100 | H8: =(B8-B7)/B7*100 | I8: 1 | J8: =IF(I8=1,F8,"") | K8: =IF(AND(G8<=-3,H8>=5),"оба",IF(G8<=-3,"СК",IF(H8>=5,"Займ","")))
A9: 2023-12-01 | B9: 343497.7 | C9: 353304.97 | D9: 0.97224134 | E9: =D9*100 | F9: =E9-E8 | G9: =(C9-C8)/C8*100 | H9: =(B9-B8)/B8*100 | I9: 1 | J9: =IF(I9=1,F9,"") | K9: =IF(AND(G9<=-3,H9>=5),"оба",IF(G9<=-3,"СК",IF(H9>=5,"Займ","")))
A10: 2024-01-01 | B10: 372019.3 | C10: 351291.9 | D10: 1.0590034 | E10: =D10*100 | F10: =E10-E9 | G10: =(C10-C9)/C9*100 | H10: =(B10-B9)/B9*100 | I10: 0 | J10: =IF(I10=1,F10,"") | K10: =IF(AND(G10<=-3,H10>=5),"оба",IF(G10<=-3,"СК",IF(H10>=5,"Займ","")))
A11: 2024-02-01 | B11: 359821.6 | C11: 364498.16 | D11: 0.98716986 | E11: =D11*100 | F11: =E11-E10 | G11: =(C11-C10)/C10*100 | H11: =(B11-B10)/B10*100 | I11: 0 | J11: =IF(I11=1,F11,"") | K11: =IF(AND(G11<=-3,H11>=5),"оба",IF(G11<=-3,"СК",IF(H11>=5,"Займ","")))
A12: 2024-03-01 | B12: 371215.4 | C12: 384072.88 | D12: 0.96652334 | E12: =D12*100 | F12: =E12-E11 | G12: =(C12-C11)/C11*100 | H12: =(B12-B11)/B11*100 | I12: 1 | J12: =IF(I12=1,F12,"") | K12: =IF(AND(G12<=-3,H12>=5),"оба",IF(G12<=-3,"СК",IF(H12>=5,"Займ","")))
A13: 2024-04-01 | B13: 363473 | C13: 396208.88 | D13: 0.91737722 | E13: =D13*100 | F13: =E13-E12 | G13: =(C13-C12)/C12*100 | H13: =(B13-B12)/B12*100 | I13: 1 | J13: =IF(I13=1,F13,"") | K13: =IF(AND(G13<=-3,H13>=5),"оба",IF(G13<=-3,"СК",IF(H13>=5,"Займ","")))
A14: 2024-05-01 | B14: 357665.7 | C14: 401188.39 | D14: 0.89151559 | E14: =D14*100 | F14: =E14-E13 | G14: =(C14-C13)/C13*100 | H14: =(B14-B13)/B13*100 | I14: 1 | J14: =IF(I14=1,F14,"") | K14: =IF(AND(G14<=-3,H14>=5),"оба",IF(G14<=-3,"СК",IF(H14>=5,"Займ","")))
A15: 2024-06-01 | B15: 360756.5 | C15: 403780.01 | D15: 0.89344814 | E15: =D15*100 | F15: =E15-E14 | G15: =(C15-C14)/C14*100 | H15: =(B15-B14)/B14*100 | I15: 1 | J15: =IF(I15=1,F15,"") | K15: =IF(AND(G15<=-3,H15>=5),"оба",IF(G15<=-3,"СК",IF(H15>=5,"Займ","")))
A16: 2024-07-01 | B16: 362413.9 | C16: 405247.49 | D16: 0.89430265 | E16: =D16*100 | F16: =E16-E15 | G16: =(C16-C15)/C15*100 | H16: =(B16-B15)/B15*100 | I16: 1 | J16: =IF(I16=1,F16,"") | K16: =IF(AND(G16<=-3,H16>=5),"оба",IF(G16<=-3,"СК",IF(H16>=5,"Займ","")))
A17: 2024-08-01 | B17: 358163.4 | C17: 417859.74 | D17: 0.85713785 | E17: =D17*100 | F17: =E17-E16 | G17: =(C17-C16)/C16*100 | H17: =(B17-B16)/B16*100 | I17: 1 | J17: =IF(I17=1,F17,"") | K17: =IF(AND(G17<=-3,H17>=5),"оба",IF(G17<=-3,"СК",IF(H17>=5,"Займ","")))
... A40: 2026-07-01 | B40: 448999.7 | C40: 442346.33 | D40: 1.0150411 | E40: =D40*100 | F40: =E40-E39 | G40: =(C40-C39)/C39*100 | H40: =(B40-B39)/B39*100 | I40: 1 | J40: =IF(I40=1,F40,"") | K40: =IF(AND(G40<=-3,H40>=5),"оба",IF(G40<=-3,"СК",IF(H40>=5,"Займ","")))
A42: Колонка I — база метода B. Ноль стоит у двух приростов, примыкающих к максимуму ряда (2024-01-01): вход в выброс и выход из него. Это определение восстановлено обратным счётом от опубликованных 113,17 и в тексте методов не приведено — см. DISCLOSURE.md, Р-Д1. Колонка J гасит эти два значения, поэтому STDEVP по ней считает σ метода B, а STDEV по F — σ методов D и H.

Sheet Параметры
A1: Параметры расчёта
A2: Всё, что не выводится из ряда. Меняется здесь — пересчитывается везде.
A4: Параметр | B4: Обозначение | C4: Значение | D4: Откуда
A5: Квантиль нормального для 0,90 | B5: z(0,90) | C5: 1.2815516 | D5: Стандартное нормальное распределение. Проверка в самом Excel: =NORMSINV(0,9) даёт то же число
A6: Отношение баз капитала | B6: k (Г26) | C6: 0.87453 | D6: E_балансовый / E_регуляторный на 01.01.2026. Находка Г26: с 01.01.2026 знаменатель метрики сменил базу, уровень при этом не пересматривался
A7: Уровень в регуляторной базе | B7: L_рег | C7: 95 | D7: Действующий уровень риск-аппетита по топ-20. Приложение № 3 к Политике (VND-02). История уровня: 250 % → 95 %, см. data/top20_limit_history.csv
A8: Длина цикла реагирования, мес. | B8: T | C8: 3 | D8: ДОПУЩЕНИЕ, не измеренная величина. Пока длина цикла не закреплена в регламенте, метод H держится на ней со слов — DISCLOSURE § 6
A9: Порог триггера по капиталу, % | B9: порог ΔСК | C9: -3 | D9: Месячное падение СК, при котором наблюдение ускоряется независимо от зоны
A10: Порог триггера по портфелю, % | B10: порог ΔЗайм | C10: 5 | D10: Месячный рост задолженности топ-20, при котором наблюдение ускоряется
A12: T = 3 — единственный параметр здесь, у которого нет внешнего источника. Если на комитете спросят «почему три месяца», честный ответ: длина цикла решения не измерена, и это записано как незакрытый пункт. Поставьте другое число в C8 — вся книга пересчитается, и станет видно, что уровень от этого меняется на 1,4–1,5 пп за каждый месяц цикла.

Sheet Расчёт
A1: Расчётный лист: формула, вход, результат
A2: Колонка D считается формулой из листов «Ряд» и «Параметры». Колонка E — то, что напечатано в DECOMPOSITION § 11.10 и DISCLOSURE § 2. Колонка G должна быть «да» во всех строках: иначе опубликованное число разошлось с расчётом.
A4: Показатель | B4: Формула словами | C4: Формула в этой книге | D4: Значение | E4: Опубликовано | F4: Расхождение | G4: Сходится | H4: Где напечатано
A5: 1. База: что даёт сам ряд
A6: σ_Δ — с.к.о. месячных приростов | B6: выборочное с.к.о. (n−1) по всем 35 приростам | C6: STDEV(d) | D6: =STDEV(d) | E6: 4.0667 | F6: =D6-E6 | G6: =IF(ABS(F6)<=0.00005,"да","НЕТ") | H6: DISCLOSURE § 2.1
A7: σ метода B | B7: популяционное с.к.о. приростов без двух, примыкающих к выбросу 01.2024 | C7: STDEVP(dB) | D7: =STDEVP(dB) | E7: 3.6326 | F7: =D7-E7 | G7: =IF(ABS(F7)<=0.00005,"да","НЕТ") | H7: DISCLOSURE Р-Д1
A8: σ уровней (метод М1) | B8: выборочное с.к.о. самих значений ряда, не приростов | C8: STDEV(v) | D8: =STDEV(v) | E8: 6.2201 | F8: =D8-E8 | G8: =IF(ABS(F8)<=0.00005,"да","НЕТ") | H8: DISCLOSURE Р-Д1
A9: Текущая точка, 01.07.2026 | B9: последнее значение ряда | C9: 'Ряд'!E40 | D9: ='Ряд'!E40 | E9: 101.5041 | F9: =D9-E9 | G9: =IF(ABS(F9)<=0.00005,"да","НЕТ") | H9: DISCLOSURE § 2.1
A10: Максимум ряда, 01.2024 | B10: наибольшее значение ряда | C10: MAX(v) | D10: =MAX(v) | E10: 105.9003 | F10: =D10-E10 | G10: =IF(ABS(F10)<=0.00005,"да","НЕТ") | H10: DISCLOSURE § 2.1
A11: Число точек | B11: сколько наблюдений в ряде | C11: COUNT(v) | D11: =COUNT(v) | E11: 36 | F11: =D11-E11 | G11: =IF(ABS(F11)<=0.5,"да","НЕТ") | H11: DISCLOSURE § 1
A12: 2. Уровень
A13: L — уровень в балансовой базе | B13: действующий уровень 95 %, пересчитанный под балансовый капитал: L_рег / k | C13: L_reg/k_G26 | D13: =L_reg/k_G26 | E13: 108.6298 | F13: =D13-E13 | G13: =IF(ABS(F13)<=0.00005,"да","НЕТ") | H13: DISCLOSURE § 2.2
A14: Это одна величина в двух системах измерения, а не два разных лимита. Фраза «пробит лимит 95 % по балансовому капиталу» — категориальная ошибка: числитель берётся из одной базы, знаменатель из другой.
A15: 3. Запас на реагирование M(T) = z(0,90) · σ_Δ · √T и жёлтая линия L − M(T)
A16: Запас M(T) при T = 1 | B16: z(0,90) × σ_Δ × корень из T | C16: z_90*D6*SQRT(1) | D16: =z_90*D6*SQRT(1) | E16: 5.2117 | F16: =D16-E16 | G16: =IF(ABS(F16)<=0.00005,"да","НЕТ") | H16: DISCLOSURE § 2.3
A17: Жёлтая линия при T = 1 | B17: L − M(T) | C17: D13-D16 | D17: =D13-D16 | E17: 103.418 | F17: =D17-E17 | G17: =IF(ABS(F17)<=0.00005,"да","НЕТ") | H17: DISCLOSURE § 2.3
A18: Наблюдений выше жёлтой, T = 1 | B18: сколько точек ряда не ниже жёлтой линии | C18: COUNTIF(v,">="&D17) | D18: =COUNTIF(v,">="&D17) | E18: 1 | F18: =D18-E18 | G18: =IF(ABS(F18)<=0.5,"да","НЕТ") | H18: DISCLOSURE § 2.3, Р-Д3
A19: Доля времени выше жёлтой, T = 1 | B19: их доля от 36 наблюдений | C19: COUNTIF(v,">="&D17)/COUNT(v)*100 | D19: =COUNTIF(v,">="&D17)/COUNT(v)*100 | E19: 2.8 | F19: =D19-E19 | G19: =IF(ABS(F19)<=0.05,"да","НЕТ") | H19: DISCLOSURE § 2.3, Р-Д3
A20: Запас M(T) при T = 2 | B20: z(0,90) × σ_Δ × корень из T | C20: z_90*D6*SQRT(2) | D20: =z_90*D6*SQRT(2) | E20: 7.3705 | F20: =D20-E20 | G20: =IF(ABS(F20)<=0.00005,"да","НЕТ") | H20: DISCLOSURE § 2.3
A21: Жёлтая линия при T = 2 | B21: L − M(T) | C21: D13-D20 | D21: =D13-D20 | E21: 101.2593 | F21: =D21-E21 | G21: =IF(ABS(F21)<=0.00005,"да","НЕТ") | H21: DISCLOSURE § 2.3
A22: Наблюдений выше жёлтой, T = 2 | B22: сколько точек ряда не ниже жёлтой линии | C22: COUNTIF(v,">="&D21) | D22: =COUNTIF(v,">="&D21) | E22: 2 | F22: =D22-E22 | G22: =IF(ABS(F22)<=0.5,"да","НЕТ") | H22: DISCLOSURE § 2.3, Р-Д3
A23: Доля времени выше жёлтой, T = 2 | B23: их доля от 36 наблюдений | C23: COUNTIF(v,">="&D21)/COUNT(v)*100 | D23: =COUNTIF(v,">="&D21)/COUNT(v)*100 | E23: 5.6 | F23: =D23-E23 | G23: =IF(ABS(F23)<=0.05,"да","НЕТ") | H23: DISCLOSURE § 2.3, Р-Д3
A24: Запас M(T) при T = 3 | B24: z(0,90) × σ_Δ × корень из T | C24: z_90*D6*SQRT(3) | D24: =z_90*D6*SQRT(3) | E24: 9.027 | F24: =D24-E24 | G24: =IF(ABS(F24)<=0.00005,"да","НЕТ") | H24: DISCLOSURE § 2.3
A25: Жёлтая линия при T = 3 | B25: L − M(T) | C25: D13-D24 | D25: =D13-D24 | E25: 99.6028 | F25: =D25-E25 | G25: =IF(ABS(F25)<=0.00005,"да","НЕТ") | H25: DISCLOSURE § 2.3
A26: Наблюдений выше жёлтой, T = 3 | B26: сколько точек ряда не ниже жёлтой линии | C26: COUNTIF(v,">="&D25) | D26: =COUNTIF(v,">="&D25) | E26: 4 | F26: =D26-E26 | G26: =IF(ABS(F26)<=0.5,"да","НЕТ") | H26: DISCLOSURE § 2.3, Р-Д3
A27: Доля времени выше жёлтой, T = 3 | B27: их доля от 36 наблюдений | C27: COUNTIF(v,">="&D25)/COUNT(v)*100 | D27: =COUNTIF(v,">="&D25)/COUNT(v)*100 | E27: 11.1 | F27: =D27-E27 | G27: =IF(ABS(F27)<=0.05,"да","НЕТ") | H27: DISCLOSURE § 2.3, Р-Д3
A28: Запас M(T) при T = 4 | B28: z(0,90) × σ_Δ × корень из T | C28: z_90*D6*SQRT(4) | D28: =z_90*D6*SQRT(4) | E28: 10.4235 | F28: =D28-E28 | G28: =IF(ABS(F28)<=0.00005,"да","НЕТ") | H28: DISCLOSURE § 2.3
A29: Жёлтая линия при T = 4 | B29: L − M(T) | C29: D13-D28 | D29: =D13-D28 | E29: 98.2063 | F29: =D29-E29 | G29: =IF(ABS(F29)<=0.00005,"да","НЕТ") | H29: DISCLOSURE § 2.3
A30: Наблюдений выше жёлтой, T = 4 | B30: сколько точек ряда не ниже жёлтой линии | C30: COUNTIF(v,">="&D29) | D30: =COUNTIF(v,">="&D29) | E30: 6 | F30: =D30-E30 | G30: =IF(ABS(F30)<=0.5,"да","НЕТ") | H30: DISCLOSURE § 2.3, Р-Д3
A31: Доля времени выше жёлтой, T = 4 | B31: их доля от 36 наблюдений | C31: COUNTIF(v,">="&D29)/COUNT(v)*100 | D31: =COUNTIF(v,">="&D29)/COUNT(v)*100 | E31: 16.7 | F31: =D31-E31 | G31: =IF(ABS(F31)<=0.05,"да","НЕТ") | H31: DISCLOSURE § 2.3, Р-Д3
A32: Р-Д3: доля в процентах от 36 наблюдений читается точнее, чем есть. 2,8 % — это одно наблюдение, 11,1 % — четыре. На комитете доля называется только вместе с числом наблюдений, поэтому строка «Наблюдений» стоит выше строки «Доля», а не под ней.
A33: 4. Квантили ряда (метод C). Линейная интерполяция между порядковыми статистиками
A34: Квантиль 85 % | B34: значение, ниже которого лежит 85 % ряда | C34: PERCENTILE(v,0.85) | D34: =PERCENTILE(v,0.85) | E34: 98.1887 | F34: =D34-E34 | G34: =IF(ABS(F34)<=0.00005,"да","НЕТ") | H34: DISCLOSURE § 2.5
A35: Квантиль 90 % | B35: значение, ниже которого лежит 90 % ряда | C35: PERCENTILE(v,0.90) | D35: =PERCENTILE(v,0.90) | E35: 99.5485 | F35: =D35-E35 | G35: =IF(ABS(F35)<=0.00005,"да","НЕТ") | H35: DISCLOSURE § 2.5
A36: Квантиль 95 % | B36: значение, ниже которого лежит 95 % ряда | C36: PERCENTILE(v,0.95) | D36: =PERCENTILE(v,0.95) | E36: 101.0117 | F36: =D36-E36 | G36: =IF(ABS(F36)<=0.00005,"да","НЕТ") | H36: DISCLOSURE § 2.5
A37: 5. Два независимых пути к одному уровню
A38: Метод H: квантиль 90 % + запас T = 3 | B38: квантиль₉₀(v) + M(3) | C38: D35+D24 | D38: =D35+D24 | E38: 108.5755 | F38: =D38-E38 | G38: =IF(ABS(F38)<=0.00005,"да","НЕТ") | H38: DISCLOSURE § 2.4
A39: Расхождение двух путей | B39: L (пересчёт базы) − H (цикл решения) | C39: D13-D38 | D39: =D13-D38 | E39: 0.0543 | F39: =D39-E39 | G39: =IF(ABS(F39)<=0.00005,"да","НЕТ") | H39: DISCLOSURE § 2.4
A40: Главный довод против упрёка «уровень подогнан под факт»: пути не связаны по построению. Первый смотрит на отношение баз капитала, второй — на распределение ряда и длину процесса. Сходятся на 0,05 пп.
A41: 6. Производные метрики
...

Sheet Три сигмы
A1: Р-Д1: в таблице восьми методов три разные σ
A2: Это первый вопрос, который задаст любой, кто читает таблицу методов внимательно. Ответ лучше дать самому, до вопроса.
A4: Методы | B4: Какая σ | C4: Значение | D4: К σ_Δ | E4: Что из этого следует
A5: D, H | B5: выборочное с.к.о. приростов, все 35 | C5: ='Расчёт'!D6 | D5: =C5/'Расчёт'!D6 | E5: Базовая. На ней стоят запас M(T) и расстояние D
A6: B | B6: популяционное с.к.о. приростов без двух, примыкающих к выбросу 01.2024 | C6: ='Расчёт'!D7 | D6: =C6/'Расчёт'!D6 | E6: На 11 % меньше базовой — и метод получает за это более высокую жёлтую линию. Основание исключать режимный выброс есть, но в тексте методов оно не написано и восстановлено обратным счётом от опубликованных 113,17
A7: М1 | B7: выборочное с.к.о. самих уровней, не приростов | C7: ='Расчёт'!D8 | D7: =C7/'Расчёт'!D6 | E7: Мера разброса уровня за три года, а не месячного хода. С первыми двумя несопоставима в принципе
A9: Что с этим делать. Либо привести все методы к одной σ, либо назвать σ каждого прямо в строке таблицы методов. Второе честнее: у метода B есть содержательное основание исключать режимный выброс — но основание должно быть написано, а не восстанавливаться обратным счётом. Метод, защищаемый в собственных терминах, несравним с методом, защищаемым в своих.

Sheet Триггеры
A1: Триггеры на движение: ΔСК ≤ −3 % или ΔЗайм ≥ +5 % за месяц
A2: Срабатывают независимо от зоны. Все 35 приростов показаны целиком — выборка из шести строк была бы недоказуема: не видно, что остальные 29 условию не отвечают.
A4: Дата | B4: ΔСК, % | C4: ΔЗайм, % | D4: Коэффициент | E4: Что сработало
A5: ='Ряд'!A6 | B5: ='Ряд'!G6 | C5: ='Ряд'!H6 | D5: ='Ряд'!E6 | E5: ='Ряд'!K6
A6: ='Ряд'!A7 | B6: ='Ряд'!G7 | C6: ='Ряд'!H7 | D6: ='Ряд'!E7 | E6: ='Ряд'!K7
A7: ='Ряд'!A8 | B7: ='Ряд'!G8 | C7: ='Ряд'!H8 | D7: ='Ряд'!E8 | E7: ='Ряд'!K8
A8: ='Ряд'!A9 | B8: ='Ряд'!G9 | C8: ='Ряд'!H9 | D8: ='Ряд'!E9 | E8: ='Ряд'!K9
A9: ='Ряд'!A10 | B9: ='Ряд'!G10 | C9: ='Ряд'!H10 | D9: ='Ряд'!E10 | E9: ='Ряд'!K10
A10: ='Ряд'!A11 | B10: ='Ряд'!G11 | C10: ='Ряд'!H11 | D10: ='Ряд'!E11 | E10: ='Ряд'!K11
A11: ='Ряд'!A12 | B11: ='Ряд'!G12 | C11: ='Ряд'!H12 | D11: ='Ряд'!E12 | E11: ='Ряд'!K12
A12: ='Ряд'!A13 | B12: ='Ряд'!G13 | C12: ='Ряд'!H13 | D12: ='Ряд'!E13 | E12: ='Ряд'!K13
A13: ='Ряд'!A14 | B13: ='Ряд'!G14 | C13: ='Ряд'!H14 | D13: ='Ряд'!E14 | E13: ='Ряд'!K14
A14: ='Ряд'!A15 | B14: ='Ряд'!G15 | C14: ='Ряд'!H15 | D14: ='Ряд'!E15 | E14: ='Ряд'!K15
A15: ='Ряд'!A16 | B15: ='Ряд'!G16 | C15: ='Ряд'!H16 | D15: ='Ряд'!E16 | E15: ='Ряд'!K16
A16: ='Ряд'!A17 | B16: ='Ряд'!G17 | C16: ='Ряд'!H17 | D16: ='Ряд'!E17 | E16: ='Ряд'!K17
... A39: ='Ряд'!A40 | B39: ='Ряд'!G40 | C39: ='Ряд'!H40 | D39: ='Ряд'!E40 | E39: ='Ряд'!K40
A41: Сработало | B41: =COUNTIF(E5:E39,"Займ")+COUNTIF(E5:E39,"СК")+COUNTIF(E5:E39,"оба") | C41: =B41/35*100 | D41: из 35 приростов, %
A43: Строка 01.2026 — та, ради которой триггеры и заводятся: вход сделан капиталом (ΔСК = −7,92 %), а не портфелем, и уровневая зона его не предупреждала в принципе. Зона смотрит на значение коэффициента, триггер — на его движение; это разные инструменты, и один другого не заменяет.
